Workbook
Name \0: #REF!
Name \3: #N/A
Name \4: #N/A
Name \a: #REF!
Name \b: #N/A
Name \C: #REF!
Name \d: #REF!
Name \E: #REF!
Name \f: #N/A
Name \g: #REF!
Name \h: #REF!
Name \P: #REF!
Name \q: #N/A
Name \r: #REF!
Name \s: #REF!
Name \TB_1: #REF!
Name \TB_3: #REF!
Name \TB_4: #REF!
Name \TB_5: #REF!
Name \TB_6: #REF!
Name \TB_7: #REF!
Name \TB_8: #REF!
Name \TB_9: #REF!
Name \W: #REF!
Name \x: #REF!
Name \z: #REF!
Name \ㅈㅂ: #REF!
Name _: #N/A
Name _.12: #REF!
Name _.dbf: #REF!
Name __: #N/A
Name ___: #N/A
Name ____: #N/A
Name _____: #N/A
Name ______: #N/A
Name _______________KY1: #REF!
Name ______________KY1: #REF!
Name _____________KY1: #REF!
Name ____________dep08: #REF!
Name ____________KY1: #REF!
Name ____________to020831: #REF!
Name ____________x2: #REF!
Name ____________X4: #REF!
Name ___________dep08: #REF!
Name ___________KY1: #REF!
Name ___________to020831: #REF!
Name ___________x2: #REF!
Name ___________X4: #REF!
Name __________dep08: #REF!
Name __________KY1: #REF!
Name __________to020831: #REF!
Name __________x2: #REF!
Name __________X4: #REF!
Name _________dep08: #REF!
Name _________KY1: #REF!
Name _________to020831: #REF!
Name _________x2: #REF!
Name _________X4: #REF!
Name ________dep08: #REF!
Name ________KY1: #REF!

Sheet 回报测算-EVEBITDA（核心假设）
A1: 龙岛竹项目
A2: 交易假设
H3: 2021 | I3: 2022 | J3: 2023 | L3: 2024 | M3: 2025 | N3: 2026 | O3: 2027 | P3: 2028 | Q3: 2029 | R3: 2030
H4: 历史 | I4: 历史 | J4: 历史 | K4: 历史 | L4: 预测 | M4: 预测 | N4: 预测 | O4: 预测 | P4: 预测 | Q4: 预测 | R4: 预测
A5: 交易假设 | H5: 44561 | I5: 44926 | J5: 45291 | K5: 10M2024 | L5: 45657 | M5: 46022 | N5: 46387 | O5: 46752 | P5: 46753 | Q5: 47483 | R5: 47848
A6: 百万元美元
A8: x | B8: 基本假设
B10: 估值日期 | F10: 46022
B11: 预测情景 | F11: 2 | G11: <1=乐观情景；2=基准情景；3=悲观情景
B12: 一年天数 | F12: 365
A15: x | B15: 交易结构
B17: 第一步：老股
B18: 估值假设
B19: 企业价值 | G19: 1130
C20: 2025 EBITDA | G20: =利润表!N44 -> 131.26853 | H20: 2024 EBITDA | I20: =利润表!L44 -> 105.49078 | J20: 2026 EBITDA | K20: =利润表!O44 -> 154.33576
C21: 2025 EV/EBITDA | G21: =G19/G20 -> 8.6083086 | H21: 2024 EV/EBITDA | I21: =G19/I20 -> 10.711837 | J21: 2026 EV/EBITDA | K21: =G19/K20 -> 7.3216993
C22: Add: Net Debt | G22: =资产负债表!M95 -> -434.2701
B24: 股权价值 | G24: =G19+G22 -> 695.7299
C25: 2025 Net Profit | G25: =利润表!N40 -> 55.900017 | H25: 2024 Net Profit | I25: =利润表!L40 -> 37.933253 | J25: 2026 Net Profit | K25: =利润表!O40 -> 81.940585
C26: 2025 PE | G26: =G24/G25 -> 12.445969 | H26: 2024 PE | I26: =G24/I25 -> 18.340898 | J26: 2026 PE | K26: =G24/K25 -> 8.4906631
B28: 创始人股东留存比例 | G28: 0.3497
B30: 投资人出资金额 | G30: =G24*G37 -> 452.43315
B32: 股权结构
F33: 本次交易前 | G33: 本次交易后
B34: 常总 | F34: 0.3497 | G34: =G28 -> 0.3497
B35: 机构股东 | F35: =11.28%+10.68%+4.64% -> 0.266
B36: 自然人股东 | F36: =1-SUM(F34:F35) -> 0.3843
B37: CPE | G37: =1-G34 -> 0.6503
B38: 合计 | F38: =SUM(F34:F37) -> 1 | G38: =SUM(G34:G37) -> 1
B40: 第二步：增资
B42: 投资人出资金额 | G42: 100 | H42: 假设用于还债金额 | J42: =G42/2 -> 50
B44: 股权结构
F45: 本次交易前 | G45: 本次交易后 | H45: ESOP后
B46: 常总 | F46: =G34 -> 0.3497 | G46: =G24*G28/(G24+G42) -> 0.30575293 | H46: =G46*(1-H49) -> 0.27517763
B47: 机构股东
B48: 自然人股东
B49: ESOP | H49: 0.1
B50: CPE | F50: =G37 -> 0.6503 | G50: =1-SUM(G46:G49) -> 0.69424707 | H50: =1-SUM(H46:H49) -> 0.62482237
B51: 合计 | F51: =SUM(F46:F50) -> 1 | G51: =SUM(G46:G50) -> 1 | H51: =SUM(H46:H50) -> 1
B53: 合计
...

Sheet 回报测算-PE（仅供参考）
A1: 龙岛竹项目
A2: 交易假设
H3: 2021 | I3: 2022 | J3: 2023 | L3: 2024 | M3: 2025 | N3: 2026 | O3: 2027 | P3: 2028 | Q3: 2029 | R3: 2030
H4: 历史 | I4: 历史 | J4: 历史 | K4: 历史 | L4: 预测 | M4: 预测 | N4: 预测 | O4: 预测 | P4: 预测 | Q4: 预测 | R4: 预测
A5: 交易假设 | H5: 44561 | I5: 44926 | J5: 45291 | K5: 10M2024 | L5: 45657 | M5: 46022 | N5: 46387 | O5: 46752 | P5: 46753 | Q5: 47483 | R5: 47848
A6: 百万元美元
A8: x | B8: 基本假设
B10: 估值日期 | F10: ='回报测算-EVEBITDA（核心假设）'!F10 -> 46022
B11: 一年天数 | F11: ='回报测算-EVEBITDA（核心假设）'!F12 -> 365
A14: x | B14: 交易结构
B16: 第一步：老股
B17: 估值假设
B18: 企业价值 | G18: =G23-G21 -> 1075.5736
C19: 2025 EBITDA | G19: =利润表!N44 -> 131.26853 | H19: 2024 EBITDA | I19: =利润表!L44 -> 105.49078 | J19: 2026 EBITDA | K19: =利润表!O44 -> 154.33576
C20: 2025 EV/EBITDA | G20: =G18/G19 -> 8.1936897 | H20: 2024 EV/EBITDA | I20: =G18/I19 -> 10.195902 | J20: 2026 EV/EBITDA | K20: =G18/K19 -> 6.96905
C21: Add: Net Debt | G21: =资产负债表!N87 -> -379.8437
B23: 股权价值 | G23: =G24*G25 -> 695.7299
C24: 2025 Net Profit | G24: =利润表!N40 -> 55.900017 | H24: 2024 Net Profit | I24: =利润表!L40 -> 37.933253 | J24: 2026 Net Profit | K24: =利润表!O40 -> 81.940585
C25: 2025 PE | G25: ='回报测算-EVEBITDA（核心假设）'!G26 -> 12.445969 | H25: 2024 PE | I25: ='回报测算-EVEBITDA（核心假设）'!I26 -> 18.340898 | J25: 2026 PE | K25: =G23/K24 -> 8.4906631
B27: 创始人股东留存比例 | G27: 0.3497
B29: 投资人出资金额 | G29: =G23*G36 -> 452.43315
B31: 股权结构
F32: 本次交易前 | G32: 本次交易后
B33: 常总 | F33: 0.3497 | G33: =G27 -> 0.3497
B34: 机构股东 | F34: =11.28%+10.68%+4.64% -> 0.266
B35: 自然人股东 | F35: =1-SUM(F33:F34) -> 0.3843
B36: 投资人 | G36: =1-G33 -> 0.6503
B37: 合计 | F37: =SUM(F33:F36) -> 1 | G37: =SUM(G33:G36) -> 1
B39: 第二步：增资
B41: 投资人出资金额 | G41: 100
B43: 股权结构
F44: 本次交易前 | G44: 本次交易后
B45: 常总 | F45: =G33 -> 0.3497 | G45: =G23*G27/(G23+G41) -> 0.30575293
B46: 机构股东
B47: 自然人股东
B48: 投资人 | F48: =G36 -> 0.6503 | G48: =1-G45 -> 0.69424707
B49: 合计 | F49: =SUM(F45:F48) -> 1 | G49: =SUM(G45:G48) -> 1
B51: 合计
B53: 投资人出资金额合计 | G53: =G29+G41 -> 552.43315
B54: 投资人股权比例 | G54: =G48 -> 0.69424707
...

Sheet Output_财务
E2: 2021 | F2: 2022 | G2: 2023 | H2: 2024 | I2: 2024 | J2: 2025 | K2: 2025 | L2: 2026 | M2: 2027 | N2: 2028 | O2: 2029 | P2: 2030 | Q2: 21-24 | R2: 25-30
B3: 百万美元 | H3: M1-10 | J3: M1-7 | Q3: CAGR | R3: CAGR
B4: 集团总营收 | E4: =集团!H23 -> 1025.8019 | F4: =集团!I23 -> 1065.4785 | G4: =集团!J23 -> 964.25071 | H4: =集团!K23 -> 882 | I4: =集团!L23 -> 1058.2698 | J4: =集团!M23 -> 616.84498 | K4: =集团!N23 -> 1151.4887 | L4: =集团!O23 -> 1290.0069 | ... P4: =集团!S23 -> 1941.201 | Q4: =POWER(I4/E4,1/3)-1 -> 0.010441019 | R4: =POWER(P4/K4,1/5)-1 -> 0.11010016
B5: 美国业务营收 | E5: =集团!H17 -> 659.601 | F5: =集团!I17 -> 700.555 | G5: =集团!J17 -> 554.271 | H5: =集团!K17 -> 485.036 | I5: =集团!L17 -> 585.56 | J5: =集团!M17 -> 320.78878 | K5: =集团!N17 -> 592.40612 | L5: =集团!O17 -> 643.74939 | ... P5: =集团!S17 -> 876.00838 | Q5: =POWER(I5/E5,1/3)-1 -> -0.038911533 | R5: =POWER(P5/K5,1/5)-1 -> 0.081378537
B6: 1）渠道商客户 | E6: =美国!H76/1000 -> 362.428 | F6: =美国!I76/1000 -> 402.137 | G6: =美国!J76/1000 -> 406.39304 | H6: =美国!K76/1000 -> 349.968 | I6: =美国!L76/1000 -> 431.68113 | J6: =美国!M76/1000 -> 246.74758 | K6: =美国!N76/1000 -> 462.41035 | L6: =美国!O76/1000 -> 507.23622 | ... P6: =美国!S76/1000 -> 663.4259 | Q6: =IFERROR(POWER(I6/E6,1/3)-1,"NA") -> 0.060019304 | R6: =IFERROR(POWER(P6/K6,1/5)-1,"NA") -> 0.07486266
C7: 沃尔玛 | E7: =美国!H115/1000 -> 157.557 | F7: =美国!I115/1000 -> 179.36 | G7: =美国!J115/1000 -> 191.188 | H7: =美国!K115/1000 -> 172.919 | I7: =美国!L115/1000 -> 208.26467 | J7: =美国!M115/1000 -> 120.33345 | K7: =美国!N115/1000 -> 210.01375 | L7: =美国!O115/1000 -> 231.17776 | ... P7: =美国!S115/1000 -> 302.95306 | Q7: =IFERROR(POWER(I7/E7,1/3)-1,"NA") -> 0.097469937 | R7: =IFERROR(POWER(P7/K7,1/5)-1,"NA") -> 0.076032837
C8: Costco | E8: =美国!H156/1000 -> 64.846 | F8: =美国!I156/1000 -> 81.303 | G8: =美国!J156/1000 -> 70.143 | H8: =美国!K156/1000 -> 55.752 | I8: =美国!L156/1000 -> 76.79135 | J8: =美国!M156/1000 -> 40.847854 | K8: =美国!N156/1000 -> 85.956038 | L8: =美国!O156/1000 -> 93.147555 | ... P8: =美国!S156/1000 -> 128.93995 | Q8: =IFERROR(POWER(I8/E8,1/3)-1,"NA") -> 0.057977351 | R8: =IFERROR(POWER(P8/K8,1/5)-1,"NA") -> 0.084481678
C9: Sams | E9: =美国!H197/1000 -> 49.112 | F9: =美国!I197/1000 -> 43.45 | G9: =美国!J197/1000 -> 50.343036 | H9: =美国!K197/1000 -> 49.089 | I9: =美国!L197/1000 -> 60.356157 | J9: =美国!M197/1000 -> 40.898632 | K9: =美国!N197/1000 -> 77.02712 | L9: =美国!O197/1000 -> 88.358935 | ... P9: =美国!S197/1000 -> 111.2145 | Q9: =IFERROR(POWER(I9/E9,1/3)-1,"NA") -> 0.071136094 | R9: =IFERROR(POWER(P9/K9,1/5)-1,"NA") -> 0.076226184
C10: Walgreens | E10: =美国!H238/1000 -> 41.494 | F10: =美国!I238/1000 -> 42.933 | G10: =美国!J238/1000 -> 39.695 | H10: =美国!K238/1000 -> 38.674 | I10: =美国!L238/1000 -> 48.901377 | J10: =美国!M238/1000 -> 26.152181 | K10: =美国!N238/1000 -> 52.26507 | L10: =美国!O238/1000 -> 56.705062 | ... P10: =美国!S238/1000 -> 78.915901 | Q10: =IFERROR(POWER(I10/E10,1/3)-1,"NA") -> 0.056278877 | R10: =IFERROR(POWER(P10/K10,1/5)-1,"NA") -> 0.085901907
C11: Target | E11: =美国!H279/1000 -> 14.747 | F11: =美国!I279/1000 -> 16.199 | G11: =美国!J279/1000 -> 15.04 | H11: =美国!K279/1000 -> 12.003 | I11: =美国!L279/1000 -> 13.654465 | J11: =美国!M279/1000 -> 6.6509651 | K11: =美国!N279/1000 -> 12.574106 | L11: =美国!O279/1000 -> 12.652253 | ... P11: =美国!S279/1000 -> 12.751751 | Q11: =IFERROR(POWER(I11/E11,1/3)-1,"NA") -> -0.025331345 | R11: =IFERROR(POWER(P11/K11,1/5)-1,"NA") -> 0.0028097258
C12: 其他Private Label | E12: =美国!H320/1000 -> 34.672 | F12: =美国!I320/1000 -> 38.892 | G12: =美国!J320/1000 -> 39.984 | H12: =美国!K320/1000 -> 21.531 | I12: =美国!L320/1000 -> 23.713112 | J12: =美国!M320/1000 -> 11.8645 | K12: =美国!N320/1000 -> 24.574268 | L12: =美国!O320/1000 -> 25.194655 | ... P12: =美国!S320/1000 -> 28.650741 | Q12: =IFERROR(POWER(I12/E12,1/3)-1,"NA") -> -0.1189446 | R12: =IFERROR(POWER(P12/K12,1/5)-1,"NA") -> 0.031171863
B13: 2）品牌客户 | E13: =美国!H351/1000 -> 295.685 | F13: =美国!I351/1000 -> 298.128 | G13: =美国!J351/1000 -> 163.066 | H13: =美国!K351/1000 -> 135.119 | I13: =美国!L351/1000 -> 153.57854 | J13: =美国!M351/1000 -> 74.041198 | K13: =美国!N351/1000 -> 129.99577 | L13: =美国!O351/1000 -> 131.56317 | ... P13: =美国!S351/1000 -> 133.38248 | Q13: =IFERROR(POWER(I13/E13,1/3)-1,"NA") -> -0.19616468 | R13: =IFERROR(POWER(P13/K13,1/5)-1,"NA") -> 0.0051570271
C14: GNC | E14: =美国!H390/1000 -> 152.691 | F14: =美国!I390/1000 -> 153.085 | G14: =美国!J390/1000 -> 75.841 | H14: =美国!K390/1000 -> 91.499 | I14: =美国!L390/1000 -> 106.54957 | J14: =美国!M390/1000 -> 58.784275 | K14: =美国!N390/1000 -> 100.5098 | L14: =美国!O390/1000 -> 100.5098 | ... P14: =美国!S390/1000 -> 100.5098 | Q14: =IFERROR(POWER(I14/E14,1/3)-1,"NA") -> -0.1130222 | R14: =IFERROR(POWER(P14/K14,1/5)-1,"NA") -> 0
C15: Bausch | E15: =美国!H431/1000 -> 63.113 | F15: =美国!I431/1000 -> 80.787 | G15: =美国!J431/1000 -> 63.985 | H15: =美国!K431/1000 -> 23.946 | I15: =美国!L431/1000 -> 24.543552 | J15: =美国!M431/1000 -> 2.3000617 | K15: =美国!N431/1000 -> 5.1906411 | L15: =美国!O431/1000 -> 5.1906411 | ... P15: =美国!S431/1000 -> 5.1906411 | Q15: =IFERROR(POWER(I15/E15,1/3)-1,"NA") -> -0.27008403 | R15: =IFERROR(POWER(P15/K15,1/5)-1,"NA") -> 0
C16: GSK/Haleon | E16: =美国!H472/1000 -> 37.349 | F16: =美国!I472/1000 -> 21.652 | G16: =美国!J472/1000 -> 8.502 | H16: =美国!K472/1000 -> 8.392 | I16: =美国!L472/1000 -> 9.566448 | J16: =美国!M472/1000 -> 1.4880972 | K16: =美国!N472/1000 -> 2.8595866 | L16: =美国!O472/1000 -> 2.9246711 | ... P16: =美国!S472/1000 -> 3.1295568 | Q16: =IFERROR(POWER(I16/E16,1/3)-1,"NA") -> -0.36492662 | R16: =IFERROR(POWER(P16/K16,1/5)-1,"NA") -> 0.018206622
C17: Herbalife | E17: =美国!H513/1000 -> 16.38 | F17: =美国!I513/1000 -> 21.374 | G17: =美国!J513/1000 -> 6.75 | H17: =美国!K513/1000 -> 6.567 | I17: =美国!L513/1000 -> 7.7659503 | J17: =美国!M513/1000 -> 8.8605518 | K17: =美国!N513/1000 -> 15.127232 | L17: =美国!O513/1000 -> 16.629546 | ... P17: =美国!S513/1000 -> 18.243972 | Q17: =IFERROR(POWER(I17/E17,1/3)-1,"NA") -> -0.22024129 | R17: =IFERROR(POWER(P17/K17,1/5)-1,"NA") -> 0.038178384
C18: Garden of Life | E18: =美国!H554/1000 -> 4.607 | F18: =美国!I554/1000 -> 8.51 | G18: =美国!J554/1000 -> 3.554 | H18: =美国!K554/1000 -> 2.676 | I18: =美国!L554/1000 -> 2.8420598 | J18: =美国!M554/1000 -> 0.69204336 | K18: =美国!N554/1000 -> 2.8420598 | L18: =美国!O554/1000 -> 2.8420598 | ... P18: =美国!S554/1000 -> 2.8420598 | Q18: =IFERROR(POWER(I18/E18,1/3)-1,"NA") -> -0.14872149 | R18: =IFERROR(POWER(P18/K18,1/5)-1,"NA") -> 0
C19: 其他品牌 | E19: =美国!H595/1000 -> 21.545 | F19: =美国!I595/1000 -> 12.72 | G19: =美国!J595/1000 -> 4.434 | H19: =美国!K595/1000 -> 2.039 | I19: =美国!L595/1000 -> 2.3109657 | J19: =美国!M595/1000 -> 1.9161692 | K19: =美国!N595/1000 -> 3.4664486 | L19: =美国!O595/1000 -> 3.4664486 | ... P19: =美国!S595/1000 -> 3.4664486 | Q19: =IFERROR(POWER(I19/E19,1/3)-1,"NA") -> -0.52486648 | R19: =IFERROR(POWER(P19/K19,1/5)-1,"NA") -> 0
B20: 3）电商客户 | E20: =美国!H618/1000 -> 0 | F20: =美国!I618/1000 -> 0 | G20: =美国!J618/1000 -> 15 | H20: =美国!K618/1000 -> 0 | I20: =美国!L618/1000 -> 0 | J20: =美国!M618/1000 -> 0 | K20: =美国!N618/1000 -> 0 | L20: =美国!O618/1000 -> 5 | ... P20: =美国!S618/1000 -> 80 | Q20: =IFERROR(POWER(I20/E20,1/3)-1,"NA") -> NA | R20: =IFERROR(POWER(P20/K20,1/5)-1,"NA") -> NA
B21: 中国业务营收 | E21: =集团!H18 -> 224.35545 | F21: =集团!I18 -> 246.82577 | G21: =集团!J18 -> 256.76242 | H21: =集团!K18 -> 281.01007 | I21: =集团!L18 -> 340.42412 | J21: =集团!M18 -> 200.35544 | K21: =集团!N18 -> 351.14744 | L21: =集团!O18 -> 401.70701 | ... P21: =集团!S18 -> 665.79562 | Q21: =POWER(I21/E21,1/3)-1 -> 0.14910901 | R21: =POWER(P21/K21,1/5)-1 -> 0.13650221
B22: 1）供应链事业部 | E22: =集团!H38 -> 195.25029 | F22: =集团!I38 -> 211.48 | G22: =集团!J38 -> 229.41864 | H22: =集团!K38 -> 254.915 | I22: =集团!L38 -> 308.17399 | J22: =集团!M38 -> 167.37715 | K22: =集团!N38 -> 295.36291 | L22: =集团!O38 -> 338.08722 | ... P22: =集团!S38 -> 558.87125 | Q22: =IFERROR(POWER(I22/E22,1/3)-1,"NA") -> 0.16430857 | R22: =IFERROR(POWER(P22/K22,1/5)-1,"NA") -> 0.13603356
B23: 集团内供应链（Intra-group supply chain） | E23: =集团!H33 -> 101.5452 | F23: =集团!I33 -> 104.87117 | G23: =集团!J33 -> 101.49864 | H23: =集团!K33 -> 119.29838 | I23: =集团!L33 -> 145.12678 | J23: =集团!M33 -> 60.699922 | K23: =集团!N33 -> 98.637921 | L23: =集团!O33 -> 89.428172 | ... P23: =集团!S33 -> 84.642785 | Q23: =IFERROR(POWER(I23/E23,1/3)-1,"NA") -> 0.12640884 | R23: =IFERROR(POWER(P23/K23,1/5)-1,"NA") -> -0.030139645
C24: Intra-group: Aland US | E24: =中国!H106/集团!H9/1000 -> 86.471951 | F24: =中国!I106/集团!I9/1000 -> 94.994502 | G24: =中国!J106/集团!J9/1000 -> 85.98955 | H24: =中国!K106/集团!K9/1000 -> 102.00754 | I24: =中国!L106/集团!L9/1000 -> 124.02503 | J24: =中国!M106/集团!M9/1000 -> 50.13302 | K24: =中国!N106/集团!N9/1000 -> 76.75673 | L24: =中国!O106/集团!O9/1000 -> 66.638032 | ... P24: =中国!S106/集团!S9/1000 -> 52.800837 | Q24: =IFERROR(POWER(I24/E24,1/3)-1,"NA") -> 0.12774618 | R24: =IFERROR(POWER(P24/K24,1/5)-1,"NA") -> -0.072092108
C25: Intra-group: Brunel | E25: =中国!H145/集团!H9/1000 -> 13.4155 | F25: =中国!I145/集团!I9/1000 -> 7.2861813 | G25: =中国!J145/集团!J9/1000 -> 11.702564 | H25: =中国!K145/集团!K9/1000 -> 11.73507 | I25: =中国!L145/集团!L9/1000 -> 13.960172 | J25: =中国!M145/集团!M9/1000 -> 6.5369166 | K25: =中国!N145/集团!N9/1000 -> 12.964217 | L25: =中国!O145/集团!O9/1000 -> 13.052844 | ... P25: =中国!S145/集团!S9/1000 -> 17.46565 | Q25: =IFERROR(POWER(I25/E25,1/3)-1,"NA") -> 0.013354265 | R25: =IFERROR(POWER(P25/K25,1/5)-1,"NA") -> 0.061421031
C26: Intra-group: Vita Health | E26: =中国!H184/集团!H9/1000 -> 0 | F26: =中国!I184/集团!I9/1000 -> 0.15720654 | G26: =中国!J184/集团!J9/1000 -> 2.0727635 | H26: =中国!K184/集团!K9/1000 -> 3.8592958 | I26: =中国!L184/集团!L9/1000 -> 4.7709558 | J26: =中国!M184/集团!M9/1000 -> 3.455556 | K26: =中国!N184/集团!N9/1000 -> 6.3857266 | L26: =中国!O184/集团!O9/1000 -> 7.7738388 | ... P26: =中国!S184/集团!S9/1000 -> 12.431066 | Q26: =IFERROR(POWER(I26/E26,1/3)-1,"NA") -> NA | R26: =IFERROR(POWER(P26/K26,1/5)-1,"NA") -> 0.14250894
C27: Intra-group:Pragen | E27: =中国!H223/集团!H9/1000 -> 1.4724897 | F27: =中国!I223/集团!I9/1000 -> 2.3347697 | G27: =中国!J223/集团!J9/1000 -> 1.5740741 | H27: =中国!K223/集团!K9/1000 -> 1.575493 | I27: =中国!L223/集团!L9/1000 -> 2.2503221 | J27: =中国!M223/集团!M9/1000 -> 0.41774084 | K27: =中国!N223/集团!N9/1000 -> 2.2917667 | L27: =中国!O223/集团!O9/1000 -> 1.6042367 | ... P27: =中国!S223/集团!S9/1000 -> 1.2954212 | Q27: =IFERROR(POWER(I27/E27,1/3)-1,"NA") -> 0.15185412 | R27: =IFERROR(POWER(P27/K27,1/5)-1,"NA") -> -0.10782898
C28: Intra-group:Bloem | E28: =中国!H262/集团!H9/1000 -> 0.1852627 | F28: =中国!I262/集团!I9/1000 -> 0.098514116 | G28: =中国!J262/集团!J9/1000 -> 0.15968661 | H28: =中国!K262/集团!K9/1000 -> 0.12098592 | I28: =中国!L262/集团!L9/1000 -> 0.12029889 | J28: =中国!M262/集团!M9/1000 -> 0.15668847 | K28: =中国!N262/集团!N9/1000 -> 0.2394802 | L28: =中国!O262/集团!O9/1000 -> 0.35922029 | ... P28: =中国!S262/集团!S9/1000 -> 0.64981155 | Q28: =IFERROR(POWER(I28/E28,1/3)-1,"NA") -> -0.13405319 | R28: =IFERROR(POWER(P28/K28,1/5)-1,"NA") -> 0.22096598
B29: 中国内部供应链（Supply Chain to other China BU） | E29: =集团!H34 -> 9.9666682 | F29: =集团!I34 -> 10.355126 | G29: =集团!J34 -> 9.5740741 | H29: =集团!K34 -> 4.7573239 | I29: =集团!L34 -> 5.4257526 | J29: =集团!M34 -> 3.135209 | K29: =集团!N34 -> 5.4005496 | L29: =集团!O34 -> 5.4005496 | ... P29: =集团!S34 -> 5.4005496 | Q29: =IFERROR(POWER(I29/E29,1/3)-1,"NA") -> -0.18347404 | R29: =IFERROR(POWER(P29/K29,1/5)-1,"NA") -> 0
B30: 本土客户（Domestic CDMO） | E30: =集团!H35 -> 27.261828 | F30: =集团!I35 -> 40.663595 | G30: =集团!J35 -> 64.243217 | H30: =集团!K35 -> 73.839296 | I30: =集团!L35 -> 88.265893 | J30: =集团!M35 -> 57.238345 | K30: =集团!N35 -> 110.77105 | L30: =集团!O35 -> 143.34842 | ... P30: =集团!S35 -> 288.92717 | Q30: =IFERROR(POWER(I30/E30,1/3)-1,"NA") -> 0.47937854 | R30: =IFERROR(POWER(P30/K30,1/5)-1,"NA") -> 0.21135776
C31: Sams | E31: =中国!H367/1000/集团!H9 -> 4.715518 | F31: =中国!I367/1000/集团!I9 -> 10.950775 | G31: =中国!J367/1000/集团!J9 -> 19.370456 | H31: =中国!K367/1000/集团!K9 -> 26.391972 | I31: =中国!L367/1000/集团!L9 -> 30.705018 | J31: =中国!M367/1000/集团!M9 -> 19.033978 | K31: =中国!N367/1000/集团!N9 -> 37.331337 | L31: =中国!O367/1000/集团!O9 -> 48.860189 | ... P31: =中国!S367/1000/集团!S9 -> 86.410488 | Q31: =IFERROR(POWER(I31/E31,1/3)-1,"NA") -> 0.86735397 | R31: =IFERROR(POWER(P31/K31,1/5)-1,"NA") -> 0.18276532
C32: T（妈妈花园） | E32: =中国!H406/1000/集团!H9 -> 4.6705522 | F32: =中国!I406/1000/集团!I9 -> 11.003783 | G32: =中国!J406/1000/集团!J9 -> 15.028415 | H32: =中国!K406/1000/集团!K9 -> 15.243662 | I32: =中国!L406/1000/集团!L9 -> 17.679611 | J32: =中国!M406/1000/集团!M9 -> 9.3028896 | K32: =中国!N406/1000/集团!N9 -> 16.41703 | L32: =中国!O406/1000/集团!O9 -> 19.081557 | ... P32: =中国!S406/1000/集团!S9 -> 39.408625 | Q32: =IFERROR(POWER(I32/E32,1/3)-1,"NA") -> 0.55848092 | R32: =IFERROR(POWER(P32/K32,1/5)-1,"NA") -> 0.19140478
C33: B（健敏思） | E33: =中国!H445/1000/集团!H9 -> 0.44199495 | F33: =中国!I445/1000/集团!I9 -> 1.9063827 | G33: =中国!J445/1000/集团!J9 -> 6.8808108 | H33: =中国!K445/1000/集团!K9 -> 10.900563 | I33: =中国!L445/1000/集团!L9 -> 12.528589 | J33: =中国!M445/1000/集团!M9 -> 9.1347497 | K33: =中国!N445/1000/集团!N9 -> 16.809579 | L33: =中国!O445/1000/集团!O9 -> 23.41202 | ... P33: =中国!S445/1000/集团!S9 -> 40.767813 | Q33: =IFERROR(POWER(I33/E33,1/3)-1,"NA") -> 2.0490295 | R33: =IFERROR(POWER(P33/K33,1/5)-1,"NA") -> 0.19385646
C34: 京东 | E34: =中国!H484/1000/集团!H9 -> 0 | F34: =中国!I484/1000/集团!I9 -> 1.4589701 | G34: =中国!J484/1000/集团!J9 -> 4.0525665 | H34: =中国!K484/1000/集团!K9 -> 5.495493 | I34: =中国!L484/1000/集团!L9 -> 7.0570116 | J34: =中国!M484/1000/集团!M9 -> 5.783593 | K34: =中国!N484/1000/集团!N9 -> 12.175952 | L34: =中国!O484/1000/集团!O9 -> 15.828738 | ... P34: =中国!S484/1000/集团!S9 -> 43.717948 | Q34: =IFERROR(POWER(I34/E34,1/3)-1,"NA") -> NA | R34: =IFERROR(POWER(P34/K34,1/5)-1,"NA") -> 0.29131253
C35: 其他 (现有+新增) | E35: =中国!H523/1000/集团!H9 -> 17.433763 | F35: =中国!I523/1000/集团!I9 -> 15.343685 | G35: =中国!J523/1000/集团!J9 -> 18.910969 | H35: =中国!K523/1000/集团!K9 -> 15.807606 | I35: =中国!L523/1000/集团!L9 -> 20.295663 | J35: =中国!M523/1000/集团!M9 -> 13.983135 | K35: =中国!N523/1000/集团!N9 -> 28.037148 | L35: =中国!O523/1000/集团!O9 -> 36.16591 | ... P35: =中国!S523/1000/集团!S9 -> 78.622301 | Q35: =IFERROR(POWER(I35/E35,1/3)-1,"NA") -> 0.05197166 | R35: =IFERROR(POWER(P35/K35,1/5)-1,"NA") -> 0.22902972
D36: 现有其他客户 | E36: =中国!H562/1000/集团!H9 -> 17.433763 | F36: =中国!I562/1000/集团!I9 -> 15.343685 | G36: =中国!J562/1000/集团!J9 -> 18.910969 | H36: =中国!K562/1000/集团!K9 -> 15.807606 | I36: =中国!L562/1000/集团!L9 -> 20.295663 | J36: =中国!M562/1000/集团!M9 -> 13.983135 | K36: =中国!N562/1000/集团!N9 -> 28.037148 | L36: =中国!O562/1000/集团!O9 -> 33.515197 | ... P36: =中国!S562/1000/集团!S9 -> 57.453518 | Q36: =IFERROR(POWER(I36/E36,1/3)-1,"NA") -> 0.05197166 | R36: =IFERROR(POWER(P36/K36,1/5)-1,"NA") -> 0.15429432
D37: 新增客户 | E37: =中国!H601/1000/集团!H9 -> 0 | F37: =中国!I601/1000/集团!I9 -> 0 | G37: =中国!J601/1000/集团!J9 -> 0 | H37: =中国!K601/1000/集团!K9 -> 0 | I37: =中国!L601/1000/集团!L9 -> 0 | J37: =中国!M601/1000/集团!M9 -> 0 | K37: =中国!N601/1000/集团!N9 -> 0 | L37: =中国!O601/1000/集团!O9 -> 2.6507135 | ... P37: =中国!S601/1000/集团!S9 -> 21.168783 | Q37: =IFERROR(POWER(I37/E37,1/3)-1,"NA") -> NA | R37: =IFERROR(POWER(P37/K37,1/5)-1,"NA") -> NA
B38: 全球CDMO业务（International CDMO） | E38: =集团!H36 -> 49.409636 | F38: =集团!I36 -> 50.15385 | G38: =集团!J36 -> 50.040883 | H38: =集团!K36 -> 55.44169 | I38: =集团!L36 -> 67.013607 | J38: =集团!M36 -> 44.28466 | K38: =集团!N36 -> 78.222313 | L38: =集团!O36 -> 97.579006 | ... P38: =集团!S36 -> 177.56966 | Q38: =IFERROR(POWER(I38/E38,1/3)-1,"NA") -> 0.10692224 | R38: =IFERROR(POWER(P38/K38,1/5)-1,"NA") -> 0.17816908
C39: Dr Max | E39: =中国!H667/1000/集团!H9 -> 6.6911281 | F39: =中国!I667/1000/集团!I9 -> 9.3237741 | G39: =中国!J667/1000/集团!J9 -> 8.3837607 | H39: =中国!K667/1000/集团!K9 -> 7.8188732 | I39: =中国!L667/1000/集团!L9 -> 10.670718 | J39: =中国!M667/1000/集团!M9 -> 9.8714495 | K39: =中国!N667/1000/集团!N9 -> 17.186499 | L39: =中国!O667/1000/集团!O9 -> 23.322022 | ... P39: =中国!S667/1000/集团!S9 -> 35.296127 | Q39: =IFERROR(POWER(I39/E39,1/3)-1,"NA") -> 0.16832794 | R39: =IFERROR(POWER(P39/K39,1/5)-1,"NA") -> 0.15480306
C40: Medpharm | E40: =中国!H731/1000/集团!H9 -> 2.3342166 | F40: =中国!I731/1000/集团!I9 -> 3.3301396 | G40: =中国!J731/1000/集团!J9 -> 3.0635328 | H40: =中国!K731/1000/集团!K9 -> 3.8959155 | I40: =中国!L731/1000/集团!L9 -> 4.8867595 | J40: =中国!M731/1000/集团!M9 -> 3.6562238 | K40: =中国!N731/1000/集团!N9 -> 6.3430533 | L40: =中国!O731/1000/集团!O9 -> 8.148145 | ... P40: =中国!S731/1000/集团!S9 -> 13.001919 | Q40: =IFERROR(POWER(I40/E40,1/3)-1,"NA") -> 0.2792633 | R40: =IFERROR(POWER(P40/K40,1/5)-1,"NA") -> 0.15436146
C41: Jamieson | E41: =中国!H770/1000/集团!H9 -> 4.0323382 | F41: =中国!I770/1000/集团!I9 -> 5.2402037 | G41: =中国!J770/1000/集团!J9 -> 3.0079772 | H41: =中国!K770/1000/集团!K9 -> 3.823662 | I41: =中国!L770/1000/集团!L9 -> 4.6803624 | J41: =中国!M770/1000/集团!M9 -> 4.5193389 | K41: =中国!N770/1000/集团!N9 -> 7.1093086 | L41: =中国!O770/1000/集团!O9 -> 8.5311703 | ... P41: =中国!S770/1000/集团!S9 -> 11.380794 | Q41: =IFERROR(POWER(I41/E41,1/3)-1,"NA") -> 0.050930935 | R41: =IFERROR(POWER(P41/K41,1/5)-1,"NA") -> 0.098674495
...

Sheet Output_产能
B2: 千美元 | E2: 历史 | F2: 历史 | G2: 历史 | H2: 历史 | I2: 历史 | J2: 历史 | K2: 预测 | L2: 预测 | M2: 预测 | N2: 预测 | O2: 预测 | P2: 预测
E3: 44561 | F3: 44926 | G3: 45291 | H3: 10M2024 | I3: 45657 | J3: 7M2025 | K3: 46022 | L3: 46387 | M3: 46752 | N3: 46753 | O3: 47483 | P3: 47848
B4: CAPEX汇总
B5: 合计资本支出 | K5: =K6+K7 -> 40917.024 | L5: =L6+L7 -> 55368.612 | M5: =M6+M7 -> 61102.84 | N5: =N6+N7 -> 37659.926 | O5: =O6+O7 -> 26198.935 | P5: =P6+P7 -> 21180.028
B6: 维护性资本支出 | K6: =产能及CAPEX!O20 -> 17089 | L6: =产能及CAPEX!P20 -> 17759.101 | M6: =产能及CAPEX!Q20 -> 18496.211 | N6: =产能及CAPEX!R20 -> 19307.032 | O6: =产能及CAPEX!S20 -> 20198.935 | P6: =产能及CAPEX!T20 -> 21180.028
B7: 扩张性资本支出 | K7: =SUM(K8:K16) -> 23828.024 | L7: =SUM(L8:L16) -> 37609.511 | M7: =SUM(M8:M16) -> 42606.63 | N7: =SUM(N8:N16) -> 18352.895 | O7: =SUM(O8:O16) -> 6000 | P7: =SUM(P8:P16) -> 0
C8: CN | D8: 硬胶囊扩产 | K8: =产能及CAPEX!O73 -> 1307.0346 | L8: =产能及CAPEX!P73 -> 0 | M8: =产能及CAPEX!Q73 -> 0 | N8: =产能及CAPEX!R73 -> 0 | O8: =产能及CAPEX!S73 -> 0 | P8: =产能及CAPEX!T73 -> 0
C9: CN | D9: 软糖扩产 | K9: =产能及CAPEX!O86 -> 13944.957 | L9: =产能及CAPEX!P86 -> 0 | M9: =产能及CAPEX!Q86 -> 0 | N9: =产能及CAPEX!R86 -> 0 | O9: =产能及CAPEX!S86 -> 0 | P9: =产能及CAPEX!T86 -> 0
C10: CN | D10: 软胶囊扩产 | K10: =产能及CAPEX!O99 -> 3776.0326 | L10: =产能及CAPEX!P99 -> 0 | M10: =产能及CAPEX!Q99 -> 18124.956 | N10: =产能及CAPEX!R99 -> 0 | O10: =产能及CAPEX!S99 -> 0 | P10: =产能及CAPEX!T99 -> 0
C11: CN | D11: 粉剂扩产 | K11: =产能及CAPEX!O125 -> 0 | L11: =产能及CAPEX!P125 -> 6835.0793 | M11: =产能及CAPEX!Q125 -> 1952.8798 | N11: =产能及CAPEX!R125 -> 976.4399 | O11: =产能及CAPEX!S125 -> 0 | P11: =产能及CAPEX!T125 -> 0
C12: CN | D12: 液体扩产 | K12: =产能及CAPEX!O134 -> 0 | L12: =产能及CAPEX!P134 -> 12169.231 | M12: =产能及CAPEX!Q134 -> 18323.592 | N12: =产能及CAPEX!R134 -> 7171.2536 | O12: =产能及CAPEX!S134 -> 0 | P12: =产能及CAPEX!T134 -> 0
C13: US | D13: 软糖扩产 | K13: =产能及CAPEX!O188 -> 4800 | L13: =产能及CAPEX!P188 -> 14400 | M13: =产能及CAPEX!Q188 -> 0 | N13: =产能及CAPEX!R188 -> 0 | O13: =产能及CAPEX!S188 -> 0 | P13: =产能及CAPEX!T188 -> 0
C14: US | D14: IT系统搭建 | K14: =产能及CAPEX!O221 -> 0 | L14: =产能及CAPEX!P221 -> 4205.2012 | M14: =产能及CAPEX!Q221 -> 4205.2012 | N14: =产能及CAPEX!R221 -> 4205.2012 | O14: =产能及CAPEX!S221 -> 0 | P14: =产能及CAPEX!T221 -> 0
C15: EU | K15: =产能及CAPEX!O274 -> 0 | L15: =产能及CAPEX!P274 -> 0 | M15: =产能及CAPEX!Q274 -> 0 | N15: =产能及CAPEX!R274 -> 3000 | O15: =产能及CAPEX!S274 -> 3000 | P15: =产能及CAPEX!T274 -> 0
C16: CA | K16: =产能及CAPEX!O234 -> 0 | L16: =产能及CAPEX!P234 -> 0 | M16: =产能及CAPEX!Q234 -> 0 | N16: =产能及CAPEX!R234 -> 3000 | O16: =产能及CAPEX!S234 -> 3000 | P16: =产能及CAPEX!T234 -> 0
B18: 中国
B19: 硬胶囊
C20: 现有产能（百万粒） | K20: =产能及CAPEX!O65 -> 0 | L20: =产能及CAPEX!P65 -> 3280 | M20: =产能及CAPEX!Q65 -> 3280 | N20: =产能及CAPEX!R65 -> 3280 | O20: =产能及CAPEX!S65 -> 3280 | P20: =产能及CAPEX!T65 -> 3280
C21: 新建产能（百万粒） | K21: =产能及CAPEX!O66 -> 3280 | L21: =产能及CAPEX!P66 -> 0 | M21: =产能及CAPEX!Q66 -> 0 | N21: =产能及CAPEX!R66 -> 0 | O21: =产能及CAPEX!S66 -> 0 | P21: =产能及CAPEX!T66 -> 0
C22: 合计产能（百万粒） | K22: =产能及CAPEX!O67 -> 3280 | L22: =产能及CAPEX!P67 -> 3280 | M22: =产能及CAPEX!Q67 -> 3280 | N22: =产能及CAPEX!R67 -> 3280 | O22: =产能及CAPEX!S67 -> 3280 | P22: =产能及CAPEX!T67 -> 3280
C23: 销量（百万粒） | E23: =产能及CAPEX!I71 -> 419.82591 | F23: =产能及CAPEX!J71 -> 427.10401 | G23: =产能及CAPEX!K71 -> 380.95016 | H23: =产能及CAPEX!L71 -> 747.717 | I23: =产能及CAPEX!M71 -> 936.50617 | J23: =产能及CAPEX!N71 -> 654.70895 | K23: =产能及CAPEX!O71 -> 1174.6825 | L23: =产能及CAPEX!P71 -> 1490.0377 | ... P23: =产能及CAPEX!T71 -> 2794.0134
C24: 产能利用率% | K24: =K23/K22 -> 0.3581349 | L24: =L23/L22 -> 0.45427978 | M24: =M23/M22 -> 0.55961486 | N24: =N23/N22 -> 0.65626983 | O24: =O23/O22 -> 0.75506664 | P24: =P23/P22 -> 0.85183336
B26: 软糖
C27: 现有产能（百万粒） | E27: =产能及CAPEX!I78 -> 2000 | F27: =产能及CAPEX!J78 -> 2000 | G27: =产能及CAPEX!K78 -> 2000 | H27: =产能及CAPEX!L78 -> 2000 | I27: =产能及CAPEX!M78 -> 2000 | J27: =产能及CAPEX!N78 -> 1166.6667 | K27: =产能及CAPEX!O78 -> 2000 | L27: =产能及CAPEX!P78 -> 3000 | ... P27: =产能及CAPEX!T78 -> 4500
C28: 新建产能（百万粒） | E28: =产能及CAPEX!I79 -> 0 | F28: =产能及CAPEX!J79 -> 0 | G28: =产能及CAPEX!K79 -> 0 | H28: =产能及CAPEX!L79 -> 0 | I28: =产能及CAPEX!M79 -> 0 | J28: =产能及CAPEX!N79 -> 0 | K28: =产能及CAPEX!O79 -> 1000 | L28: =产能及CAPEX!P79 -> 1500 | ... P28: =产能及CAPEX!T79 -> 0
C29: 合计产能（百万粒） | E29: =产能及CAPEX!I80 -> 2000 | F29: =产能及CAPEX!J80 -> 2000 | G29: =产能及CAPEX!K80 -> 2000 | H29: =产能及CAPEX!L80 -> 2000 | I29: =产能及CAPEX!M80 -> 2000 | J29: =产能及CAPEX!N80 -> 1166.6667 | K29: =产能及CAPEX!O80 -> 3000 | L29: =产能及CAPEX!P80 -> 4500 | ... P29: =产能及CAPEX!T80 -> 4500
C30: 销量（百万粒） | E30: =产能及CAPEX!I84 -> 426.98919 | F30: =产能及CAPEX!J84 -> 895.47079 | G30: =产能及CAPEX!K84 -> 1102.6769 | H30: =产能及CAPEX!L84 -> 1615.178 | I30: =产能及CAPEX!M84 -> 1882.6144 | J30: =产能及CAPEX!N84 -> 1097.2551 | K30: =产能及CAPEX!O84 -> 2069.3068 | L30: =产能及CAPEX!P84 -> 2312.8766 | ... P30: =产能及CAPEX!T84 -> 3291.0619
C31: 产能利用率% | K31: =K30/K29 -> 0.68976892 | L31: =L30/L29 -> 0.51397258 | M31: =M30/M29 -> 0.55646153 | N31: =N30/N29 -> 0.61058383 | O31: =O30/O29 -> 0.67085869 | P31: =P30/P29 -> 0.73134709
B33: 软胶囊
C34: 现有产能（百万粒） | E34: =产能及CAPEX!I91 -> 4500 | F34: =产能及CAPEX!J91 -> 4500 | G34: =产能及CAPEX!K91 -> 4500 | H34: =产能及CAPEX!L91 -> 4500 | I34: =产能及CAPEX!M91 -> 4500 | J34: =产能及CAPEX!N91 -> 2625 | K34: =产能及CAPEX!O91 -> 4500 | L34: =产能及CAPEX!P91 -> 5500 | ... P34: =产能及CAPEX!T91 -> 10300
C35: 新建产能（百万粒） | E35: =产能及CAPEX!I92 -> 0 | F35: =产能及CAPEX!J92 -> 0 | G35: =产能及CAPEX!K92 -> 0 | H35: =产能及CAPEX!L92 -> 0 | I35: =产能及CAPEX!M92 -> 0 | J35: =产能及CAPEX!N92 -> 0 | K35: =产能及CAPEX!O92 -> 1000 | L35: =产能及CAPEX!P92 -> 0 | ... P35: =产能及CAPEX!T92 -> 0
C36: 合计产能（百万粒） | E36: =产能及CAPEX!I93 -> 4500 | F36: =产能及CAPEX!J93 -> 4500 | G36: =产能及CAPEX!K93 -> 4500 | H36: =产能及CAPEX!L93 -> 4500 | I36: =产能及CAPEX!M93 -> 4500 | J36: =产能及CAPEX!N93 -> 2625 | K36: =产能及CAPEX!O93 -> 5500 | L36: =产能及CAPEX!P93 -> 5500 | ... P36: =产能及CAPEX!T93 -> 10300
C37: 销量（百万粒） | E37: =产能及CAPEX!I97 -> 2522.1613 | F37: =产能及CAPEX!J97 -> 2108.4612 | G37: =产能及CAPEX!K97 -> 3029.9361 | H37: =产能及CAPEX!L97 -> 3105.815 | I37: =产能及CAPEX!M97 -> 3740.7435 | J37: =产能及CAPEX!N97 -> 2626.3935 | K37: =产能及CAPEX!O97 -> 4317.1488 | L37: =产能及CAPEX!P97 -> 5283.2862 | ... P37: =产能及CAPEX!T97 -> 9243.903
C38: 产能利用率% | K38: =K37/K36 -> 0.78493615 | L38: =L37/L36 -> 0.96059749 | M38: =M37/M36 -> 0.60929942 | N38: =N37/N36 -> 0.70446095 | O38: =O37/O36 -> 0.80355753 | P38: =P37/P36 -> 0.89746631
B40: 片剂
C41: 现有产能（百万粒） | E41: =产能及CAPEX!I104 -> 17570 | F41: =产能及CAPEX!J104 -> 17570 | G41: =产能及CAPEX!K104 -> 17570 | H41: =产能及CAPEX!L104 -> 17570 | I41: =产能及CAPEX!M104 -> 17570 | J41: =产能及CAPEX!N104 -> 10249.167 | K41: =产能及CAPEX!O104 -> 17570 | L41: =产能及CAPEX!P104 -> 17570 | ... P41: =产能及CAPEX!T104 -> 17570
C42: 新建产能（百万粒） | E42: =产能及CAPEX!I105 -> 0 | F42: =产能及CAPEX!J105 -> 0 | G42: =产能及CAPEX!K105 -> 0 | H42: =产能及CAPEX!L105 -> 0 | I42: =产能及CAPEX!M105 -> 0 | J42: =产能及CAPEX!N105 -> 0 | K42: =产能及CAPEX!O105 -> 0 | L42: =产能及CAPEX!P105 -> 0 | ... P42: =产能及CAPEX!T105 -> 0
C43: 合计产能（百万粒） | E43: =产能及CAPEX!I106 -> 17570 | F43: =产能及CAPEX!J106 -> 17570 | G43: =产能及CAPEX!K106 -> 17570 | H43: =产能及CAPEX!L106 -> 17570 | I43: =产能及CAPEX!M106 -> 17570 | J43: =产能及CAPEX!N106 -> 10249.167 | K43: =产能及CAPEX!O106 -> 17570 | L43: =产能及CAPEX!P106 -> 17570 | ... P43: =产能及CAPEX!T106 -> 17570
C44: 销量（百万粒） | E44: =产能及CAPEX!I110 -> 12532.984 | F44: =产能及CAPEX!J110 -> 9698.5765 | G44: =产能及CAPEX!K110 -> 10550.813 | H44: =产能及CAPEX!L110 -> 12464.935 | I44: =产能及CAPEX!M110 -> 15466.286 | J44: =产能及CAPEX!N110 -> 8574.5895 | K44: =产能及CAPEX!O110 -> 14100.056 | L44: =产能及CAPEX!P110 -> 13436.567 | ... P44: =产能及CAPEX!T110 -> 16469.961
C45: 产能利用率% | K45: =K44/K43 -> 0.80250743 | L45: =L44/L43 -> 0.76474486 | M45: =M44/M43 -> 0.78466271 | N45: =N44/N43 -> 0.8265638 | O45: =O44/O43 -> 0.87738786 | P45: =P44/P43 -> 0.93739106
...

Sheet Output_区域剂型毛利
F2: 历史 | G2: 历史 | H2: 历史 | I2: 历史 | J2: 历史 | K2: 历史 | L2: 预测 | M2: 预测 | N2: 预测 | O2: 预测 | P2: 预测 | Q2: 预测
F3: 44561 | G3: 44926 | H3: 45291 | I3: 10M2024 | J3: 45657 | K3: 7M2025 | L3: 46022 | M3: 46387 | N3: 46752 | O3: 46753 | P3: 47483 | Q3: 47848
B4: 中国
C5: 硬胶囊
D6: 营业收入（千元人民币） | F6: =中国!H43+中国!H937 -> 49680.647 | G6: =中国!I43+中国!I937 -> 81224.803 | H6: =中国!J43+中国!J937 -> 69716.736 | I6: =中国!K43+中国!K937 -> 87344.5 | J6: =中国!L43+中国!L937 -> 111832.22 | K6: =中国!M43+中国!M937 -> 80578.923 | L6: =中国!N43+中国!N937 -> 142657.06 | M6: =中国!O43+中国!O937 -> 179119.7 | ... Q6: =中国!S43+中国!S937 -> 334898.69
E7: 销量（千粒） | F7: =中国!H31+中国!H913 -> 419825.91 | G7: =中国!I31+中国!I913 -> 427104.01 | H7: =中国!J31+中国!J913 -> 380950.16 | I7: =中国!K31+中国!K913 -> 747717 | J7: =中国!L31+中国!L913 -> 936506.17 | K7: =中国!M31+中国!M913 -> 654708.95 | L7: =中国!N31+中国!N913 -> 1174682.5 | M7: =中国!O31+中国!O913 -> 1490037.7 | ... Q7: =中国!S31+中国!S913 -> 2794013.4
E8: ASP（元人民币/粒） | F8: =F6/F7 -> 0.1183363 | G8: =G6/G7 -> 0.1901757 | H8: =H6/H7 -> 0.1830075 | I8: =I6/I7 -> 0.11681492 | J8: =J6/J7 -> 0.11941429 | K8: =K6/K7 -> 0.12307595 | L8: =L6/L7 -> 0.12144308 | M8: =M6/M7 -> 0.12021152 | ... Q8: =Q6/Q7 -> 0.11986295
D9: 营业成本（千元人民币） | F9: =F7*F10 -> 43147.618 | G9: =G7*G10 -> 57618.04 | H9: =H7*H10 -> 48532.289 | J9: =J7*J10 -> 75750.238 | K9: =K7*K10 -> 54841.695 | L9: =L7*L10 -> 98396.102 | M9: =M7*M10 -> 124412.69 | N9: =N7*N10 -> 152771.17 | O9: =O7*O10 -> 178585.57 | P9: =P7*P10 -> 204815.03 | Q9: =Q7*Q10 -> 230326.9
E10: 单位营业成本（元人民币/粒） | F10: =各区域分剂型成本优化!E6/10000 -> 0.10277502 | G10: =各区域分剂型成本优化!F6/10000 -> 0.134904 | H10: =各区域分剂型成本优化!G6/10000 -> 0.127398 | J10: =各区域分剂型成本优化!H6/10000 -> 0.080886 | K10: =各区域分剂型成本优化!I6/10000 -> 0.083765 | L10: =各区域分剂型成本优化!J6/10000 -> 0.083764 | M10: =各区域分剂型成本优化!K6/10000 -> 0.08349634 | N10: =各区域分剂型成本优化!L6/10000 -> 0.0832297 | O10: =各区域分剂型成本优化!M6/10000 -> 0.082964077 | P10: =各区域分剂型成本优化!N6/10000 -> 0.082699466 | Q10: =各区域分剂型成本优化!O6/10000 -> 0.082435861
D11: 毛利润（千元人民币） | F11: =F6-F9 -> 6533.0286 | G11: =G6-G9 -> 23606.764 | H11: =H6-H9 -> 21184.447 | J11: =J6-J9 -> 36081.978 | K11: =K6-K9 -> 25737.228 | L11: =L6-L9 -> 44260.957 | M11: =M6-M9 -> 54707.004 | N11: =N6-N9 -> 66366.75 | O11: =O6-O9 -> 78553.944 | P11: =P6-P9 -> 91927.884 | Q11: =Q6-Q9 -> 104571.79
D12: 毛利率 | F12: =F11/F6 -> 0.13150047 | G12: =G11/G6 -> 0.29063491 | H12: =H11/H6 -> 0.30386458 | J12: =J11/J6 -> 0.32264386 | K12: =K11/K6 -> 0.31940397 | L12: =L11/L6 -> 0.31026125 | M12: =M11/M6 -> 0.30542149 | N12: =N11/N6 -> 0.30285379 | O12: =O11/O6 -> 0.30549153 | P12: =P11/P6 -> 0.30978965 | Q12: =Q11/Q6 -> 0.31224902
C14: 软糖
D15: 营业收入（千元人民币） | F15: =中国!H44+中国!H938 -> 71178.659 | G15: =中国!I44+中国!I938 -> 210892.49 | H15: =中国!J44+中国!J938 -> 248531.67 | I15: =中国!K44+中国!K938 -> 318048.5 | J15: =中国!L44+中国!L938 -> 367659.46 | K15: =中国!M44+中国!M938 -> 196488.01 | L15: =中国!N44+中国!N938 -> 382493.87 | M15: =中国!O44+中国!O938 -> 458392.6 | ... Q15: =中国!S44+中国!S938 -> 799280.56
E16: 销量（千粒） | F16: =中国!H32+中国!H914 -> 426989.2 | G16: =中国!I32+中国!I914 -> 895470.79 | H16: =中国!J32+中国!J914 -> 1102676.9 | I16: =中国!K32+中国!K914 -> 1615178 | J16: =中国!L32+中国!L914 -> 1882614.4 | K16: =中国!M32+中国!M914 -> 1097255.1 | L16: =中国!N32+中国!N914 -> 2069306.8 | M16: =中国!O32+中国!O914 -> 2312876.6 | ... Q16: =中国!S32+中国!S914 -> 3291061.9
E17: ASP（元人民币/粒） | F17: =F15/F16 -> 0.16669897 | G17: =G15/G16 -> 0.23551018 | H17: =H15/H16 -> 0.22538938 | I17: =I15/I16 -> 0.19691235 | J17: =J15/J16 -> 0.19529197 | K17: =K15/K16 -> 0.17907231 | L17: =L15/L16 -> 0.18484155 | M17: =M15/M16 -> 0.19819155 | ... Q17: =Q15/Q16 -> 0.24286403
D18: 营业成本（千元人民币） | F18: =F16*F19 -> 53377.492 | G18: =G16*G19 -> 143331.74 | H18: =H16*H19 -> 157930.9 | J18: =J16*J19 -> 229865.33 | K18: =K16*K19 -> 135167.57 | L18: =L16*L19 -> 254913.76 | M18: =M16*M19 -> 284025.88 | N18: =N16*N19 -> 306543.51 | O18: =O16*O19 -> 335307.48 | P18: =P16*P19 -> 367258.54 | Q18: =Q16*Q19 -> 399125.31
E19: 单位营业成本（元人民币/粒） | F19: =各区域分剂型成本优化!E11/10000 -> 0.125009 | G19: =各区域分剂型成本优化!F11/10000 -> 0.160063 | H19: =各区域分剂型成本优化!G11/10000 -> 0.143225 | J19: =各区域分剂型成本优化!H11/10000 -> 0.122099 | K19: =各区域分剂型成本优化!I11/10000 -> 0.123187 | L19: =各区域分剂型成本优化!J11/10000 -> 0.123188 | M19: =各区域分剂型成本优化!K11/10000 -> 0.122802 | N19: =各区域分剂型成本优化!L11/10000 -> 0.12241777 | O19: =各区域分剂型成本优化!M11/10000 -> 0.12203529 | P19: =各区域分剂型成本优化!N11/10000 -> 0.12165455 | Q19: =各区域分剂型成本优化!O11/10000 -> 0.12127554
D20: 毛利润（千元人民币） | F20: =F15-F18 -> 17801.167 | G20: =G15-G18 -> 67560.745 | H20: =H15-H18 -> 90600.764 | J20: =J15-J18 -> 137794.13 | K20: =K15-K18 -> 61320.44 | L20: =L15-L18 -> 127580.11 | M20: =M15-M18 -> 174366.71 | N20: =N15-N18 -> 225782.36 | O20: =O15-O18 -> 283288.09 | P20: =P15-P18 -> 341823.47 | Q20: =Q15-Q18 -> 400155.25
D21: 毛利率 | F21: =F20/F15 -> 0.25009135 | G21: =G20/G15 -> 0.32035634 | H21: =H20/H15 -> 0.36454415 | J21: =J20/J15 -> 0.37478739 | K21: =K20/K15 -> 0.31208235 | L21: =L20/L15 -> 0.33354812 | M21: =M20/M15 -> 0.38038728 | N21: =N20/N15 -> 0.42414313 | O21: =O20/O15 -> 0.45795363 | P21: =P20/P15 -> 0.48206479 | Q21: =Q20/Q15 -> 0.50064429
C23: 软胶囊
D24: 营业收入（千元人民币） | F24: =中国!H45+中国!H939 -> 239289.2 | G24: =中国!I45+中国!I939 -> 261008.27 | H24: =中国!J45+中国!J939 -> 433574.39 | I24: =中国!K45+中国!K939 -> 454230 | J24: =中国!L45+中国!L939 -> 538736.91 | K24: =中国!M45+中国!M939 -> 351786.09 | L24: =中国!N45+中国!N939 -> 632839.41 | M24: =中国!O45+中国!O939 -> 811801.31 | ... Q24: =中国!S45+中国!S939 -> 1525756.5
E25: 销量（千粒） | F25: =中国!H33+中国!H915 -> 2522161.3 | G25: =中国!I33+中国!I915 -> 2108461.2 | H25: =中国!J33+中国!J915 -> 3029936.1 | I25: =中国!K33+中国!K915 -> 3105815 | J25: =中国!L33+中国!L915 -> 3740743.5 | K25: =中国!M33+中国!M915 -> 2626393.5 | L25: =中国!N33+中国!N915 -> 4317148.8 | M25: =中国!O33+中国!O915 -> 5283286.2 | ... Q25: =中国!S33+中国!S915 -> 9243903
E26: ASP（元人民币/粒） | F26: =F24/F25 -> 0.094874662 | G26: =G24/G25 -> 0.12379088 | H26: =H24/H25 -> 0.14309688 | I26: =I24/I25 -> 0.14625147 | J26: =J24/J25 -> 0.14401867 | K26: =K24/K25 -> 0.13394264 | L26: =L24/L25 -> 0.14658735 | M26: =M24/M25 -> 0.15365462 | ... Q26: =Q24/Q25 -> 0.16505544
D27: 营业成本（千元人民币） | F27: =F25*F28 -> 196922.79 | G27: =G25*G28 -> 192401.31 | H27: =H25*H28 -> 279541.9 | J27: =J25*J28 -> 323768.83 | K27: =K25*K28 -> 198248.06 | L27: =L25*L28 -> 325871.34 | M27: =M25*M28 -> 397360.19 | N27: =N25*N28 -> 470305.33 | O27: =O25*O28 -> 541799.24 | P27: =P25*P28 -> 615788.25 | Q27: =Q25*Q28 -> 685277.03
E28: 单位营业成本（元人民币/粒） | F28: =各区域分剂型成本优化!E16/10000 -> 0.078077 | G28: =各区域分剂型成本优化!F16/10000 -> 0.091252 | H28: =各区域分剂型成本优化!G16/10000 -> 0.09226 | J28: =各区域分剂型成本优化!H16/10000 -> 0.086552 | K28: =各区域分剂型成本优化!I16/10000 -> 0.075483 | L28: =各区域分剂型成本优化!J16/10000 -> 0.075483 | M28: =各区域分剂型成本优化!K16/10000 -> 0.075210801 | N28: =各区域分剂型成本优化!L16/10000 -> 0.074939693 | O28: =各区域分剂型成本优化!M16/10000 -> 0.074669671 | P28: =各区域分剂型成本优化!N16/10000 -> 0.074400731 | Q28: =各区域分剂型成本优化!O16/10000 -> 0.074132867
D29: 毛利润（千元人民币） | F29: =F24-F27 -> 42366.413 | G29: =G24-G27 -> 68606.963 | H29: =H24-H27 -> 154032.49 | J29: =J24-J27 -> 214968.08 | K29: =K24-K27 -> 153538.03 | L29: =L24-L27 -> 306968.07 | M29: =M24-M27 -> 414441.13 | N29: =N24-N27 -> 514865.24 | O29: =O24-O27 -> 616806.57 | P29: =P24-P27 -> 731726.45 | Q29: =Q24-Q27 -> 840479.43
D30: 毛利率 | F30: =F29/F24 -> 0.17705108 | G30: =G29/G24 -> 0.2628536 | H30: =H29/H24 -> 0.35526197 | J30: =J29/J24 -> 0.39902237 | K30: =K29/K24 -> 0.4364528 | L30: =L29/L24 -> 0.48506472 | M30: =M29/M24 -> 0.51052039 | N30: =N29/N24 -> 0.52261533 | O30: =O29/O24 -> 0.53236965 | P30: =P29/P24 -> 0.54301927 | Q30: =Q29/Q24 -> 0.5508608
C32: 片剂
D33: 营业收入（千元人民币） | F33: =中国!H46+中国!H940 -> 894873.01 | G33: =中国!I46+中国!I940 -> 802156.84 | H33: =中国!J46+中国!J940 -> 814751.56 | I33: =中国!K46+中国!K940 -> 916768.5 | J33: =中国!L46+中国!L940 -> 1127414.5 | K33: =中国!M46+中国!M940 -> 540631.92 | L33: =中国!N46+中国!N940 -> 926231.74 | M33: =中国!O46+中国!O940 -> 915231.52 | ... Q33: =中国!S46+中国!S940 -> 1217018.9
E34: 销量（千粒） | F34: =中国!H34+中国!H916 -> 12532984 | G34: =中国!I34+中国!I916 -> 9698576.5 | H34: =中国!J34+中国!J916 -> 10550813 | I34: =中国!K34+中国!K916 -> 12464935 | J34: =中国!L34+中国!L916 -> 15466286 | K34: =中国!M34+中国!M916 -> 8574589.5 | L34: =中国!N34+中国!N916 -> 14100056 | M34: =中国!O34+中国!O916 -> 13436567 | ... Q34: =中国!S34+中国!S916 -> 16469961
E35: ASP（元人民币/粒） | F35: =F33/F34 -> 0.071401435 | G35: =G33/G34 -> 0.082708719 | H35: =H33/H34 -> 0.077221687 | I35: =I33/I34 -> 0.073547796 | J35: =J33/J34 -> 0.072894972 | K35: =K33/K34 -> 0.063050473 | L35: =L33/L34 -> 0.065689936 | M35: =M33/M34 -> 0.068114981 | ... Q35: =Q33/Q34 -> 0.07389325
D36: 营业成本（千元人民币） | F36: =F34*F37 -> 572744.82 | G36: =G34*G37 -> 505101.87 | H36: =H34*H37 -> 493683.08 | J36: =J34*J37 -> 692069.92 | K36: =K34*K37 -> 374795.31 | L36: =L34*L37 -> 616313.43 | M36: =M34*M37 -> 585397.73 | N36: =N34*N37 -> 598688.38 | O36: =O34*O37 -> 628606.72 | P36: =P34*P37 -> 665090.18 | Q36: =Q34*Q37 -> 708267.75
E37: 单位营业成本（元人民币/粒） | F37: =各区域分剂型成本优化!E21/10000 -> 0.045699 | G37: =各区域分剂型成本优化!F21/10000 -> 0.05208 | H37: =各区域分剂型成本优化!G21/10000 -> 0.046791 | J37: =各区域分剂型成本优化!H21/10000 -> 0.044747 | K37: =各区域分剂型成本优化!I21/10000 -> 0.04371 | L37: =各区域分剂型成本优化!J21/10000 -> 0.04371 | M37: =各区域分剂型成本优化!K21/10000 -> 0.043567506 | N37: =各区域分剂型成本优化!L21/10000 -> 0.043425623 | O37: =各区域分剂型成本优化!M21/10000 -> 0.043284347 | P37: =各区域分剂型成本优化!N21/10000 -> 0.043143677 | Q37: =各区域分剂型成本优化!O21/10000 -> 0.043003608
D38: 毛利润（千元人民币） | F38: =F33-F36 -> 322128.19 | G38: =G33-G36 -> 297054.98 | H38: =H33-H36 -> 321068.48 | J38: =J33-J36 -> 435344.6 | K38: =K33-K36 -> 165836.61 | L38: =L33-L36 -> 309918.31 | M38: =M33-M36 -> 329833.8 | N38: =N33-N36 -> 360742.96 | O38: =O33-O36 -> 400614.35 | P38: =P33-P36 -> 449216.16 | Q38: =Q33-Q36 -> 508751.19
D39: 毛利率 | F39: =F38/F33 -> 0.35997084 | G39: =G38/G33 -> 0.37032032 | H39: =H38/H33 -> 0.39406918 | J39: =J38/J33 -> 0.38614422 | K39: =K38/K33 -> 0.30674588 | L39: =L38/L33 -> 0.33460127 | M39: =M38/M33 -> 0.36038291 | N39: =N38/N33 -> 0.37599664 | O39: =O38/O33 -> 0.38924033 | P39: =P38/P33 -> 0.40313525 | Q39: =Q38/Q33 -> 0.41803063
C41: 粉剂
D42: 营业收入（千元人民币） | F42: =中国!H961 -> 56372 | G42: =中国!I961 -> 109189 | H42: =中国!J961 -> 124822 | I42: =中国!K961 -> 150530 | J42: =中国!L961 -> 196300 | K42: =中国!M961 -> 201362 | L42: =中国!N961 -> 345192 | M42: =中国!O961 -> 396970.8 | ... Q42: =中国!S961 -> 694304.41
E43: 销量（吨） | F43: =中国!H951 -> 598 | G43: =中国!I951 -> 1080 | H43: =中国!J951 -> 1343 | I43: =中国!K951 -> 1637 | J43: =中国!L951 -> 2134.7446 | K43: =中国!M951 -> 2189.7934 | L43: =中国!N951 -> 3753.9315 | M43: =中国!O951 -> 4317.0212 | ... Q43: =中国!S951 -> 7550.497
E44: ASP（元人民币/吨） | F44: =F42*1000/F43 -> 94267.559 | G44: =G42*1000/G43 -> 101100.93 | H44: =H42*1000/H43 -> 92942.666 | I44: =I42*1000/I43 -> 91954.795 | J44: =J42*1000/J43 -> 91954.795 | K44: =K42*1000/K43 -> 91954.795 | L44: =L42*1000/L43 -> 91954.795 | M44: =M42*1000/M43 -> 91954.795 | ... Q44: =Q42*1000/Q43 -> 91954.795
D45: 营业成本 | F45: =-中国!H967 -> 48031 | G45: =-中国!I967 -> 97905.4 | H45: =-中国!J967 -> 109790 | J45: =-中国!L967 -> 169810 | K45: =-中国!M967 -> 123247 | L45: =-中国!N967 -> 211280.57 | M45: =-中国!O967 -> 242270.24 | N45: =-中国!P967 -> 277805.86 | O45: =-中国!Q967 -> 318554.38 | P45: =-中国!R967 -> 365280.57 | Q45: =-中国!S967 -> 418861.46
...

Sheet >>财务预测

Sheet 利润表
A1: 龙岛竹项目
A2: 利润表
H3: 2021 | I3: 2022 | J3: 2023 | L3: 2024 | N3: 2025 | O3: 2026 | P3: 2027 | Q3: 2028 | R3: 2029 | S3: 2030
H4: 历史 | I4: 历史 | J4: 历史 | K4: 历史 | L4: 历史 | M4: 历史 | N4: 预测 | O4: 预测 | P4: 预测 | Q4: 预测 | R4: 预测 | S4: 预测 | U4: CAGR
A5: 利润表 | H5: 44561 | I5: 44926 | J5: 45291 | K5: 10M2024 | L5: 45657 | M5: 7M2025 | N5: 46022 | O5: 46387 | P5: 46752 | Q5: 46753 | R5: 47483 | S5: 47848 | U5: 2025-2030
A6: 百万元美元
B8: 营业收入 | H8: =集团!H23 -> 1025.8019 | I8: =集团!I23 -> 1065.4785 | J8: =集团!J23 -> 964.25071 | K8: =集团!K23 -> 882 | L8: =集团!L23 -> 1058.2698 | M8: =集团!M23 -> 616.84498 | N8: =集团!N23 -> 1151.4887 | O8: =集团!O23 -> 1290.0069 | ... S8: =集团!S23 -> 1941.201 | U8: =POWER(S8/N8,1/5)-1 -> 0.11010016
B9: 营业成本 | H9: =H10-H8 -> -895.07466 | I9: =I10-I8 -> -877.75669 | J9: =J10-J8 -> -802.00076 | K9: =K10-K8 -> -703 | L9: =L10-L8 -> -839.13261 | M9: =M10-M8 -> -470.87412 | N9: =N10-N8 -> -899.43948 | O9: =O10-O8 -> -1007.4478 | ... S9: =S10-S8 -> -1463.444
B10: 毛利 | H10: =集团!H67 -> 130.72724 | I10: =集团!I67 -> 187.72177 | J10: =集团!J67 -> 162.24995 | K10: =集团!K67 -> 179 | L10: =集团!L67 -> 219.13719 | M10: =集团!M67 -> 145.97086 | N10: =集团!N67 -> 252.04921 | O10: =集团!O67 -> 282.55904 | ... S10: =集团!S67 -> 477.75696
C11: 毛利率% | H11: =H10/H8 -> 0.12743907 | I11: =I10/I8 -> 0.17618542 | J11: =J10/J8 -> 0.16826532 | K11: =K10/K8 -> 0.20294785 | L11: =L10/L8 -> 0.20707119 | M11: =M10/M8 -> 0.23664108 | N11: =N10/N8 -> 0.21888987 | O11: =O10/O8 -> 0.21903685 | ... S11: =S10/S8 -> 0.24611412
B13: 销售费用 | H13: =集团!H88 -> -44.568276 | I13: =集团!I88 -> -38.092794 | J13: =集团!J88 -> -37.915596 | K13: =集团!K88 -> -31 | L13: =集团!L88 -> -40.347505 | M13: =集团!M88 -> -23.934227 | N13: =集团!N88 -> -37.639351 | O13: =集团!O88 -> -41.900994 | ... S13: =集团!S88 -> -63.754307 | U13: =POWER(S13/N13,1/5)-1 -> 0.11115202
C14: 占营业收入比例% | H14: =-H13/H$8 -> 0.043447254 | I14: =-I13/I$8 -> 0.03575182 | J14: =-J13/J$8 -> 0.039321305 | K14: =-K13/K$8 -> 0.035147392 | L14: =-L13/L$8 -> 0.038125916 | M14: =-M13/M$8 -> 0.03880104 | N14: =-N13/N$8 -> 0.032687556 | O14: =-O13/O$8 -> 0.032481218 | ... S14: =-S13/S$8 -> 0.032842713
B15: 管理费用 | H15: =集团!H99 -> -71.161083 | I15: =集团!I99 -> -73.093902 | J15: =集团!J99 -> -74.654318 | K15: =集团!K99 -> -54 | L15: =集团!L99 -> -70.22689 | M15: =集团!M99 -> -47.973332 | N15: =集团!N99 -> -84.756586 | O15: =集团!O99 -> -90.293117 | ... S15: =集团!S99 -> -115.26468 | U15: =POWER(S15/N15,1/5)-1 -> 0.063419356
C16: 占营业收入比例% | H16: =-H15/H$8 -> 0.069371174 | I16: =-I15/I$8 -> 0.068601952 | J16: =-J15/J$8 -> 0.077422103 | K16: =-K15/K$8 -> 0.06122449 | L16: =-L15/L$8 -> 0.0663601 | M16: =-M15/M$8 -> 0.077772104 | N16: =-N15/N$8 -> 0.073606095 | O16: =-O15/O$8 -> 0.069994292 | ... S16: =-S15/S$8 -> 0.059378026
B17: 研发费用 | H17: =集团!H110 -> -11.727935 | I17: =集团!I110 -> -13.259454 | J17: =集团!J110 -> -13.025655 | K17: =集团!K110 -> -13 | L17: =集团!L110 -> -15.831619 | M17: =集团!M110 -> -8.7826782 | N17: =集团!N110 -> -15.620417 | O17: =集团!O110 -> -17.7669 | ... S17: =集团!S110 -> -28.870104 | U17: =POWER(S17/N17,1/5)-1 -> 0.13070977
C18: 占营业收入比例% | H18: =-H17/H$8 -> 0.011432944 | I18: =-I17/I$8 -> 0.012444601 | J18: =-J17/J$8 -> 0.013508577 | K18: =-K17/K$8 -> 0.014739229 | L18: =-L17/L$8 -> 0.014959908 | M18: =-M17/M$8 -> 0.014238064 | N18: =-N17/N$8 -> 0.013565411 | O18: =-O17/O$8 -> 0.013772717 | ... S18: =-S17/S$8 -> 0.01487229
B20: 财务费用 | H20: =集团!H121 -> -22.621444 | I20: =集团!I121 -> -17.591461 | J20: =集团!J121 -> -37.728714 | K20: =集团!K121 -> -28 | L20: =集团!L121 -> -31.783562 | M20: =集团!M121 -> -20.819237 | N20: =集团!N121 -> -35.355664 | O20: =集团!O121 -> -12.412779 | ... S20: =集团!S121 -> 7.7281966
C21: 占营业收入比例% | H21: =-H20/H$8 -> 0.022052449 | I21: =-I20/I$8 -> 0.016510386 | J21: =-J20/J$8 -> 0.039127494 | K21: =-K20/K$8 -> 0.031746032 | L21: =-L20/L$8 -> 0.030033515 | M21: =-M20/M$8 -> 0.033751165 | N21: =-N20/N$8 -> 0.030704309 | O21: =-O20/O$8 -> 0.0096222583 | ... S21: =-S20/S$8 -> -0.0039811419
B23: 其他费用和收入 | H23: =SUM(H24:H29) -> -19.373562 | I23: =SUM(I24:I29) -> -15.802816 | J23: =SUM(J24:J29) -> -17.161726 | K23: =SUM(K24:K29) -> -10 | L23: =SUM(L24:L29) -> -12.672843 | M23: =SUM(M24:M29) -> -4.2292376 | N23: =SUM(N24:N29) -> -9.4718749 | O23: =SUM(O24:O29) -> -10.229833 | ... S23: =SUM(S24:S29) -> -13.217667
C24: 税金及附加 | H24: =集团!H132 -> -3.217089 | I24: =集团!I132 -> -3.0487297 | J24: =集团!J132 -> -3.2603306 | K24: =集团!K132 -> -3 | L24: =集团!L132 -> -3.9863014 | M24: =集团!M132 -> -1.9193619 | N24: =集团!N132 -> -3.3562006 | O24: =集团!O132 -> -3.7688117 | ... S24: =集团!S132 -> -5.8507617
C25: 信用减值损失 | H25: =集团!H143 -> -1.4915059 | I25: =集团!I143 -> -0.20190607 | J25: =集团!J143 -> 0.1446659 | K25: =集团!K143 -> 0 | L25: =集团!L143 -> -0.078759 | M25: =集团!M143 -> 0 | N25: =集团!N143 -> 0 | O25: =集团!O143 -> 0 | ... S25: =集团!S143 -> 0
C26: 资产减值损失 | H26: =集团!H154 -> -20.47087 | I26: =集团!I154 -> -15.98487 | J26: =集团!J154 -> -15.342641 | K26: =集团!K154 -> -10 | L26: =集团!L154 -> -13.464615 | M26: =集团!M154 -> -5.1169888 | N26: =集团!N154 -> -10.571587 | O26: =集团!O154 -> -11.467443 | ... S26: =集团!S154 -> -15.519981
C27: 公允价值变动损益 | H27: =集团!H165 -> -0.0023691086 | I27: =集团!I165 -> -0.080874205 | J27: =集团!J165 -> -0.45697693 | K27: =集团!K165 -> 0 | L27: =集团!L165 -> 0.64161292 | M27: =集团!M165 -> -0.04150962 | N27: =集团!N165 -> 0.10791485 | O27: =集团!O165 -> 0.032382579 | ... S27: =集团!S165 -> -0.090977532
C28: 投资收益 | H28: =集团!H176 -> 3.613386 | I28: =集团!I176 -> 0.34507137 | J28: =集团!J176 -> 0.45441626 | K28: =集团!K176 -> 2 | L28: =集团!L176 -> 2.2191572 | M28: =集团!M176 -> 1.6418525 | N28: =集团!N176 -> 2.2890605 | O28: =集团!O176 -> 2.6186482 | ... S28: =集团!S176 -> 4.3401895
C29: 其他收入 | H29: =集团!H187 -> 2.1948865 | I29: =集团!I187 -> 3.1684927 | J29: =集团!J187 -> 1.2991398 | K29: =集团!K187 -> 1 | L29: =集团!L187 -> 1.9960616 | M29: =集团!M187 -> 1.2067702 | N29: =集团!N187 -> 2.0589374 | O29: =集团!O187 -> 2.3553911 | ... S29: =集团!S187 -> 3.9038629
B31: 营业利润 | H31: =SUM(H10,H13,H15,H17,H23,H20) -> -38.725056 | I31: =SUM(I10,I13,I15,I17,I23,I20) -> 29.881338 | J31: =SUM(J10,J13,J15,J17,J23,J20) -> -18.236059 | K31: =SUM(K10,K13,K15,K17,K23,K20) -> 43 | L31: =SUM(L10,L13,L15,L17,L23,L20) -> 48.27477 | M31: =SUM(M10,M13,M15,M17,M23,M20) -> 40.232153 | N31: =SUM(N10,N13,N15,N17,N23,N20) -> 69.205318 | O31: =SUM(O10,O13,O15,O17,O23,O20) -> 109.95541 | ... S31: =SUM(S10,S13,S15,S17,S23,S20) -> 264.3784
C32: 营业利润率% | H32: =H31/H$8 -> -0.037751008 | I32: =I31/I$8 -> 0.028044996 | J32: =J31/J$8 -> -0.018912155 | K32: =K31/K$8 -> 0.048752834 | L32: =L31/L$8 -> 0.045616694 | M32: =M31/M$8 -> 0.065222469 | N32: =N31/N$8 -> 0.060100736 | O32: =O31/O$8 -> 0.0852363 | ... S32: =S31/S$8 -> 0.13619321
B33: 非营业收入 | H33: =集团!H197 -> 0 | I33: =集团!I197 -> 0 | J33: =集团!J197 -> 1 | K33: =集团!K197 -> 0 | L33: =集团!L197 -> 0 | M33: =集团!M197 -> 0 | N33: =集团!N197 -> 0 | O33: =集团!O197 -> 0 | ... S33: =集团!S197 -> 0
B35: 税前利润 | H35: =H31+H33 -> -38.725056 | I35: =I31+I33 -> 29.881338 | J35: =J31+J33 -> -17.236059 | K35: =K31+K33 -> 43 | L35: =L31+L33 -> 48.27477 | M35: =M31+M33 -> 40.232153 | N35: =N31+N33 -> 69.205318 | O35: =O31+O33 -> 109.95541 | ... S35: =S31+S33 -> 264.3784
C36: 税前利润率% | H36: =H35/H$8 -> -0.037751008 | I36: =I35/I$8 -> 0.028044996 | J36: =J35/J$8 -> -0.01787508 | K36: =K35/K$8 -> 0.048752834 | L36: =L35/L$8 -> 0.045616694 | M36: =M35/M$8 -> 0.065222469 | N36: =N35/N$8 -> 0.060100736 | O36: =O35/O$8 -> 0.0852363 | ... S36: =S35/S$8 -> 0.13619321
B37: 企业所得税 | H37: =集团!H207 -> 2.9161308 | I37: =集团!I207 -> -6.1053817 | J37: =集团!J207 -> -8.5760866 | K37: =集团!K207 -> -10 | L37: =集团!L207 -> -10.341517 | M37: =集团!M207 -> -5.8702231 | N37: =集团!N207 -> -13.305301 | O37: =集团!O207 -> -28.014828 | ... S37: =集团!S207 -> -67.862918
C38: 企业所得税率% | H38: =-H37/H35 -> 0.075303462 | I38: =-I37/I35 -> 0.20432089 | J38: =-J37/J35 -> -0.49756657 | K38: =-K37/K35 -> 0.23255814 | L38: =-L37/L35 -> 0.21422199 | M38: =-M37/M35 -> 0.14590875 | N38: =-N37/N35 -> 0.19225837 | O38: =-O37/O35 -> 0.25478353 | ... S38: =-S37/S35 -> 0.25668859
B40: 净利润 | H40: =H35+H37 -> -35.808925 | I40: =I35+I37 -> 23.775957 | J40: =J35+J37 -> -25.812145 | K40: =K35+K37 -> 33 | L40: =L35+L37 -> 37.933253 | M40: =M35+M37 -> 34.36193 | N40: =N35+N37 -> 55.900017 | O40: =O35+O37 -> 81.940585 | ... S40: =S35+S37 -> 196.51548 | U40: =POWER(S40/N40,1/5)-1 -> 0.28586971
C41: 净利润率% | H41: =H40/H$8 -> -0.034908226 | I41: =I40/I$8 -> 0.022314817 | J41: =J40/J$8 -> -0.026769122 | K41: =K40/K$8 -> 0.037414966 | L41: =L40/L$8 -> 0.035844595 | M41: =M40/M$8 -> 0.05570594 | N41: =N40/N$8 -> 0.048545867 | O41: =O40/O$8 -> 0.063519495 | ... S41: =S40/S$8 -> 0.10123397
C42: yoy
B44: EBITDA | H44: =集团!H228 -> 22.203618 | I44: =集团!I228 -> 82.699851 | J44: =集团!J228 -> 50.062678 | K44: =集团!K228 -> 96 | L44: =集团!L228 -> 105.49078 | M44: =集团!M228 -> 75.14821 | N44: =N35+N48-N20 -> 131.26853 | O44: =O35+O48-O20 -> 154.33576 | P44: =P35+P48-P20 -> 190.90882 | Q44: =Q35+Q48-Q20 -> 225.52224 | R44: =R35+R48-R20 -> 261.99123 | S44: =S35+S48-S20 -> 302.50123 | U44: =POWER(S44/N44,1/5)-1 -> 0.18171652
C45: EBITDA率% | H45: =H44/H$8 -> 0.021645133 | I45: =I44/I$8 -> 0.077617573 | J45: =J44/J$8 -> 0.051918736 | K45: =K44/K$8 -> 0.10884354 | L45: =L44/L$8 -> 0.09968231 | M45: =M44/M$8 -> 0.12182673 | N45: =N44/N$8 -> 0.11399897 | O45: =O44/O$8 -> 0.11963948 | ... S45: =S44/S$8 -> 0.155832
C46: yoy | I46: =I44/H44-1 -> 2.7246114 | J46: =J44/I44-1 -> -0.39464609 | L46: =L44/J44-1 -> 1.1071741 | N46: =N44/L44-1 -> 0.24436022 | O46: =O44/N44-1 -> 0.1757255 | P46: =P44/O44-1 -> 0.23697075 | Q46: =Q44/P44-1 -> 0.18130866 | R46: =R44/Q44-1 -> 0.16170909 | S46: =S44/R44-1 -> 0.15462349
B48: 折旧与摊销 | H48: =集团!H351 -> 35.84 | I48: =集团!I351 -> 34.17 | J48: =集团!J351 -> 34.64 | K48: =集团!K351 -> 27.43313 | L48: =集团!L351 -> 33.15 | M48: =集团!M351 -> 17.94 | N48: =集团!N351 -> 26.707546 | O48: =集团!O351 -> 31.967564 | ... S48: =集团!S351 -> 45.851028

Sheet 资产负债表
A1: 龙岛竹项目
A2: 资产负债表
H3: 2021 | I3: 2022 | J3: 2023 | L3: 2024 | N3: 2025 | Q3: 2026 | R3: 2027 | S3: 2028 | T3: 2029 | U3: 2030
H4: 历史 | I4: 历史 | J4: 历史 | K4: 历史 | L4: 历史 | M4: 历史 | N4: 预测 | O4: 调整项 | P4: 增资交易后 | Q4: 预测 | R4: 预测 | S4: 预测 | T4: 预测 | U4: 预测
A5: 资产负债表 | H5: 44561 | I5: 44926 | J5: 45291 | K5: 10M2024 | L5: 45657 | M5: 7M2025 | N5: 46022 | P5: 2025E | Q5: 46387 | R5: 46752 | S5: 46753 | T5: 47483 | U5: 47848
A6: 百万元美元
G7: BS人民币/美元汇率 | H7: 6.3757 | I7: 6.9646 | J7: 7.0827 | K7: =集团!K9 -> 7.1 | L7: 7.1884 | M7: 7.1494 | N7: =M7 -> 7.1494 | O7: =N7 -> 7.1494 | P7: =N7 -> 7.1494 | Q7: =P7 -> 7.1494 | R7: =Q7 -> 7.1494 | S7: =R7 -> 7.1494 | T7: =S7 -> 7.1494 | U7: =T7 -> 7.1494
B9: 资产
C10: 流动资产
D11: 货币资金 | H11: 47.28 | I11: 68.61 | J11: 19.15 | K11: 32 | L11: 36.5 | M11: 25.37 | N11: =现金流量表!N33 -> 41.886303 | O11: ='回报测算-EVEBITDA（核心假设）'!G42-'回报测算-EVEBITDA（核心假设）'!J42-O18+O52 -> 75.439897 | P11: =N11+O11 -> 117.3262 | Q11: =现金流量表!P33 -> 127.35246 | R11: =现金流量表!Q33 -> 156.17134 | S11: =现金流量表!R33 -> 235.24163 | T11: =现金流量表!S33 -> 350.81337 | U11: =现金流量表!T33 -> 496.92084
D12: 以公允价值计量且其变动计入当期损益的金融资产 | H12: 0 | I12: 0.07 | J12: 0 | L12: 0.67 | M12: 0 | N12: =L12 -> 0.67 | P12: =N12+O12 -> 0.67 | Q12: =P12 -> 0.67 | R12: =Q12 -> 0.67 | S12: =R12 -> 0.67 | T12: =S12 -> 0.67 | U12: =T12 -> 0.67
D13: 应收票据 | H13: 1.31 | I13: 2.01 | J13: 0.37 | L13: 0.15 | M13: 0.65 | N13: =集团!N252 -> 0.63462828 | P13: =N13+O13 -> 0.63462828 | Q13: =集团!O252 -> 0.62397462 | R13: =集团!P252 -> 0.64235298 | S13: =集团!Q252 -> 0.6762456 | T13: =集团!R252 -> 0.71788642 | U13: =集团!S252 -> 0.7625216
D14: 应收账款 | H14: 145.64 | I14: 148.4 | J14: 162.41 | L14: 178.55 | M14: 164.85 | N14: =集团!N263 -> 171.16298 | P14: =N14+O14 -> 171.16298 | Q14: =集团!O263 -> 179.30377 | R14: =集团!P263 -> 193.28424 | S14: =集团!Q263 -> 211.16461 | T14: =集团!R263 -> 233.03683 | U14: =集团!S263 -> 259.49619
D15: 应收款项融资 | H15: 8.1 | I15: 0.83 | J15: 0 | L15: 0 | M15: 0 | N15: 0 | P15: =N15+O15 -> 0 | Q15: =P15 -> 0 | R15: =Q15 -> 0 | S15: =R15 -> 0 | T15: =S15 -> 0 | U15: =T15 -> 0
D16: 预付款项 | H16: 13.61 | I16: 13.09 | J16: 18.01 | L16: 22.53 | M16: 24.32 | N16: =集团!N330 -> 16.534891 | P16: =N16+O16 -> 16.534891 | Q16: =集团!O330 -> 18.511632 | R16: =集团!P330 -> 20.634715 | S16: =集团!Q330 -> 22.916557 | T16: =集团!R330 -> 25.620582 | U16: =集团!S330 -> 28.855558
D17: 应收利息 | H17: 0 | I17: 0.03 | J17: 0.01 | L17: 2.14 | M17: -0.48 | N17: =M17 -> -0.48 | P17: =N17+O17 -> -0.48 | Q17: =P17 -> -0.48 | R17: =Q17 -> -0.48 | S17: =R17 -> -0.48 | T17: =S17 -> -0.48 | U17: =T17 -> -0.48
D18: 其他应收款 | H18: 24.8 | I18: 21.28 | J18: 21.24 | L18: 23.46 | M18: 43.74 | N18: =M18 -> 43.74 | O18: =O19+O20 -> -41.971774 | P18: =N18+O18 -> 1.7682261 | Q18: =P18 -> 1.7682261 | R18: =Q18 -> 1.7682261 | S18: =R18 -> 1.7682261 | T18: =S18 -> 1.7682261 | U18: =T18 -> 1.7682261
E19: 应收关联方 | H19: =152.17/H7 -> 23.867183 | I19: =162.51/I7 -> 23.333716 | J19: =163.66/J7 -> 23.107007 | L19: =201.55/L7-5 -> 23.038228 | M19: =335.82/M7-5 -> 41.971774 | N19: =M19 -> 41.971774 | O19: =-N19 -> -41.971774 | P19: =N19+O19 -> 0 | Q19: =P19 -> 0 | R19: =Q19 -> 0 | S19: =R19 -> 0 | T19: =S19 -> 0 | U19: =T19 -> 0
E20: 其他 | H20: =H18-H19 -> 0.93281679 | I20: =I18-I19 -> -2.0537162 | J20: =J18-J19 -> -1.8670072 | L20: =L18-L19 -> 0.42177174 | M20: =M18-M19 -> 1.7682261 | N20: =M20 -> 1.7682261 | P20: =N20+O20 -> 1.7682261 | Q20: =P20 -> 1.7682261 | R20: =Q20 -> 1.7682261 | S20: =R20 -> 1.7682261 | T20: =S20 -> 1.7682261 | U20: =T20 -> 1.7682261
D21: 存货 | H21: 368.76 | I21: 371.56 | J21: 314.65 | L21: 325.06 | M21: 351.82 | N21: =集团!N296 -> 357.01008 | P21: =N21+O21 -> 357.01008 | Q21: =集团!O296 -> 382.9614 | R21: =集团!P296 -> 410.36603 | S21: =集团!Q296 -> 439.08143 | T21: =集团!R296 -> 473.95518 | U21: =集团!S296 -> 517.94943
D22: 其他流动资产 | H22: 9.77 | I22: 5.29 | J22: 6.9 | L22: 5.94 | M22: 4.62 | N22: =M22 -> 4.62 | P22: =N22+O22 -> 4.62 | Q22: =P22 -> 4.62 | R22: =Q22 -> 4.62 | S22: =R22 -> 4.62 | T22: =S22 -> 4.62 | U22: =T22 -> 4.62
C23: 流动资产合计 | H23: =SUM(H11:H18,H21:H22) -> 619.27 | I23: =SUM(I11:I18,I21:I22) -> 631.17 | J23: =SUM(J11:J18,J21:J22) -> 542.74 | L23: =SUM(L11:L18,L21:L22) -> 595 | M23: =SUM(M11:M18,M21:M22) -> 614.89 | N23: =SUM(N11:N18,N21:N22) -> 635.77889 | O23: =SUM(O11:O18,O21:O22) -> 33.468123 | P23: =SUM(P11:P18,P21:P22) -> 669.24701 | Q23: =SUM(Q11:Q18,Q21:Q22) -> 715.33147 | R23: =SUM(R11:R18,R21:R22) -> 787.67691 | S23: =SUM(S11:S18,S21:S22) -> 915.65871 | ... U23: =SUM(U11:U18,U21:U22) -> 1310.5628
C25: 非流动资产
D26: 其他权益投资工具 | H26: 2.12 | I26: 2 | J26: 1.97 | L26: 1.94 | M26: 1.95 | N26: =M26 -> 1.95 | P26: =N26+O26 -> 1.95 | Q26: =P26 -> 1.95 | R26: =Q26 -> 1.95 | S26: =R26 -> 1.95 | T26: =S26 -> 1.95 | U26: =T26 -> 1.95
D27: 长期应收款 | H27: 1.24 | I27: 2.37 | J27: 2.16 | L27: 2.1 | M27: 1.85 | N27: =M27 -> 1.85 | P27: =N27+O27 -> 1.85 | Q27: =P27 -> 1.85 | R27: =Q27 -> 1.85 | S27: =R27 -> 1.85 | T27: =S27 -> 1.85 | U27: =T27 -> 1.85
D28: 长期股权投资 | H28: 0 | I28: 0 | J28: 0.23 | L28: 0.21 | M28: 0.38 | N28: =M28 -> 0.38 | P28: =N28+O28 -> 0.38 | Q28: =P28 -> 0.38 | R28: =Q28 -> 0.38 | S28: =R28 -> 0.38 | T28: =S28 -> 0.38 | U28: =T28 -> 0.38
D29: 其他非流动金融资产 | H29: 0 | I29: 0 | J29: 0 | L29: 0 | M29: 0 | N29: =M29 -> 0 | P29: =N29+O29 -> 0 | Q29: =P29 -> 0 | R29: =Q29 -> 0 | S29: =R29 -> 0 | T29: =S29 -> 0 | U29: =T29 -> 0
D30: 投资性房地产 | H30: 0 | I30: 0 | J30: 0 | L30: 0 | M30: 0 | N30: =M30 -> 0 | P30: =N30+O30 -> 0 | Q30: =P30 -> 0 | R30: =Q30 -> 0 | S30: =R30 -> 0 | T30: =S30 -> 0 | U30: =T30 -> 0
D31: 固定资产 | H31: 238.46 | I31: 239.24 | J31: 230.08 | L31: 209.9 | M31: 215.79 | N31: ='固定资产&无形资产'!N15 -> 220.11425 | P31: =N31+O31 -> 220.11425 | Q31: ='固定资产&无形资产'!O15 -> 241.52007 | R31: ='固定资产&无形资产'!P15 -> 262.85535 | S31: ='固定资产&无形资产'!Q15 -> 257.17002 | T31: ='固定资产&无形资产'!R15 -> 237.5348 | U31: ='固定资产&无形资产'!S15 -> 210.86857
D32: 在建工程 | H32: 54.25 | I32: 45.07 | J32: 16.62 | L32: 17.95 | M32: 37.57 | N32: =L32 -> 17.95 | P32: =N32+O32 -> 17.95 | Q32: =P32 -> 17.95 | R32: =Q32 -> 17.95 | S32: =R32 -> 17.95 | T32: =S32 -> 17.95 | U32: =T32 -> 17.95
D33: 无形资产 | H33: 36.54 | I33: 31.24 | J33: 50.93 | L33: 44.51 | M33: 41.75 | N33: ='固定资产&无形资产'!N30 -> 44.51 | P33: =N33+O33 -> 44.51 | Q33: ='固定资产&无形资产'!O30 -> 44.51 | R33: ='固定资产&无形资产'!P30 -> 44.51 | S33: ='固定资产&无形资产'!Q30 -> 44.51 | T33: ='固定资产&无形资产'!R30 -> 44.51 | U33: ='固定资产&无形资产'!S30 -> 44.51
D34: 使用权资产 | H34: 35.51 | I34: 71.76 | J34: 56.53 | L34: 64.51 | M34: 66.98 | N34: =M34 -> 66.98 | P34: =N34+O34 -> 66.98 | Q34: =P34 -> 66.98 | R34: =Q34 -> 66.98 | S34: =R34 -> 66.98 | T34: =S34 -> 66.98 | U34: =T34 -> 66.98
D35: 商誉 | H35: 13.36 | I35: 12.69 | J35: 12.99 | L35: 12.92 | M35: 17.28 | N35: =M35 -> 17.28 | P35: =N35+O35 -> 17.28 | Q35: =P35 -> 17.28 | R35: =Q35 -> 17.28 | S35: =R35 -> 17.28 | T35: =S35 -> 17.28 | U35: =T35 -> 17.28
D36: 长期待摊费用 | H36: 18.92 | I36: 19.66 | J36: 10.96 | L36: 8.01 | M36: 7.05 | N36: =M36 -> 7.05 | P36: =N36+O36 -> 7.05 | Q36: =P36 -> 7.05 | R36: =Q36 -> 7.05 | S36: =R36 -> 7.05 | T36: =S36 -> 7.05 | U36: =T36 -> 7.05
D37: 递延所得税资产 | H37: 7.96 | I37: 6.66 | J37: 8.12 | L37: 8.56 | M37: 7.18 | N37: =M37 -> 7.18 | P37: =N37+O37 -> 7.18 | Q37: =P37 -> 7.18 | R37: =Q37 -> 7.18 | S37: =R37 -> 7.18 | T37: =S37 -> 7.18 | U37: =T37 -> 7.18
D38: 其他非流动资产 | H38: 10.38 | I38: 8.34 | J38: 7.72 | L38: 14.55 | M38: 8.33 | N38: =M38 -> 8.33 | P38: =N38+O38 -> 8.33 | Q38: =P38 -> 8.33 | R38: =Q38 -> 8.33 | S38: =R38 -> 8.33 | T38: =S38 -> 8.33 | U38: =T38 -> 8.33
C39: 非流动资产合计 | H39: =SUM(H26:H38) -> 418.74 | I39: =SUM(I26:I38) -> 439.03 | J39: =SUM(J26:J38) -> 398.31 | L39: =SUM(L26:L38) -> 385.16 | M39: =SUM(M26:M38) -> 406.11 | N39: =SUM(N26:N38) -> 393.57425 | O39: =SUM(O26:O38) -> 0 | P39: =SUM(P26:P38) -> 393.57425 | Q39: =SUM(Q26:Q38) -> 414.98007 | R39: =SUM(R26:R38) -> 436.31535 | S39: =SUM(S26:S38) -> 430.63002 | ... U39: =SUM(U26:U38) -> 384.32857
B40: 资产合计 | H40: =H39+H23 -> 1038.01 | I40: =I39+I23 -> 1070.2 | J40: =J39+J23 -> 941.05 | L40: =L39+L23 -> 980.16 | M40: =M39+M23 -> 1021 | N40: =N39+N23 -> 1029.3531 | O40: =O39+O23 -> 33.468123 | P40: =P39+P23 -> 1062.8213 | Q40: =Q39+Q23 -> 1130.3115 | R40: =R39+R23 -> 1223.9923 | S40: =S39+S23 -> 1346.2887 | ... U40: =U39+U23 -> 1694.8913
B42: 负债
C43: 流动负债
...

Sheet 现金流量表
A1: 龙岛竹项目
A2: 现金流量表
H3: 2021 | I3: 2022 | J3: 2023 | L3: 2024 | N3: 2025 | P3: 2026 | Q3: 2027 | R3: 2028 | S3: 2029 | T3: 2030
H4: 历史 | I4: 历史 | J4: 历史 | K4: 历史 | L4: 历史 | M4: 历史 | N4: 预测 | O4: 交易后 | P4: 预测 | Q4: 预测 | R4: 预测 | S4: 预测 | T4: 预测
A5: 现金流量表 | H5: 44561 | I5: 44926 | J5: 45291 | K5: 10M2024 | L5: 45657 | M5: 7M2025 | N5: 46022 | O5: 2025E | P5: 46387 | Q5: 46752 | R5: 46753 | S5: 47483 | T5: 47848
A6: 百万元美元
G7: 人民币/美元汇率 | H7: =集团!H9 -> 6.4503 | I7: =集团!I9 -> 6.73 | J7: =集团!J9 -> 7.02 | K7: =集团!K9 -> 7.1 | L7: =集团!L9 -> 7.1356 | M7: =集团!M9 -> 7.1689 | N7: =集团!N9 -> 7.1689 | O7: =N7 -> 7.1689 | P7: =集团!O9 -> 7.1689 | Q7: =集团!P9 -> 7.1689 | R7: =集团!Q9 -> 7.1689 | S7: =集团!R9 -> 7.1689 | T7: =集团!S9 -> 7.1689
